Workbook

Sheet EQUIPAMIENTO
A1: BUSCAR PRODUCTO: | J1: Hasta 20 coincidencias
A2: CODIGO | C2: FABRICA | D2: PUBLICO | E2: GANANCIA | F2: STOCK | G2: DESC. 5 % | H2: IVA 21 % | I2: FILA ORIGINAL | J2: Usá FILA ORIGINAL para modificar FABRICA (columna C) y STOCK (columna F) en la lista principal.
A3: {=IF(B1="","",_xlfn.LET(_xlpm.coincide,_xlfn.LAMBDA(_xlpm.t,_xlpm.p,OR(ISNUMBER(SEARCH(_xlpm.t,_xlpm.p)),OR(_xlfn.MAP(_xlfn.SEQUENCE(LEN(_xlpm.t)+1,,0),_xlfn.LAMBDA(_xlpm.k,ISNUMBER(SEARCH(LEFT(_xlpm.t,_xlpm.k)&"?"&MID(_xlpm.t,_xlpm.k+1,LEN(_xlpm.t)),_xlpm.p))))),OR(_xlfn.MAP(_xlfn.SEQUENCE(LEN(_xlpm.t)),_xlfn.LAMBDA(_xlpm.k,ISNUMBER(SEARCH(REPLACE(_xlpm.t,_xlpm.k,1,"?"),_xlpm.p))))),IF(LEN(_xlpm.t)>3,OR(_xlfn.MAP(_xlfn.SEQUENCE(LEN(_xlpm.t)),_xlfn.LAMBDA(_xlpm.k,ISNUMBER(SEARCH(REPLACE(_xlpm.t,_xlpm.k,1,""),_xlpm.p))))),FALSE))),_xlpm.terminos,_xlfn.TOCOL(_xlfn.TEXTSPLIT(LOWER(TRIM(B1))," "),1),_xlpm.productos,LOWER($B$27:$B$877),_xlpm.puntaje,_xlfn.BYROW(_xlpm.productos,_xlfn.LAMBDA(_xlpm.p,SUM(_xlfn.MAP(_xlpm.terminos,_xlfn.LAMBDA(_xlpm.t,--_xlpm.coincide(_xlpm.t,_xlpm.p)))))),_xlpm.datos,_xlfn.HSTACK($A$27:$H$877,ROW($B$27:$B$877)),IFERROR(_xlfn.TAKE(_xlfn._xlws.FILTER(_xlpm.datos,(_xlpm.puntaje=ROWS(_xlpm.terminos))*($B$27:$B$877<>"")),20),"NO ENCONTRADO")))}
A25: CODIGO | B25: PRODUCTO | C25: FABRICA | D25: PUBLICO | E25: GANANCIA | F25: STOCK | G25: DESC. 5 % | H25: IVA 21 % | L25: FABRICA BASE | M25: STOCK BASE
A26: K-17 | B26: ALFILER DE SEGURIDAD PARA PERNO | C26: =_xlfn.LET(_xlpm.x,_xlfn.XLOOKUP(ROW(),Ajustes!$A$5:$A$104,Ajustes!$D$5:$D$104,""),IF(_xlpm.x="",L26,_xlpm.x)) -> 1862 | D26: =C26*1.4 -> 2606.8 | E26: =D26-C26 -> 744.8 | F26: 10 | G26: =D26*0.95 -> 2476.46 | H26: =D26*1.21 -> 3154.228 | J26: =C26*F26 -> 18620 | K26: =E26*F26 -> 7448 | L26: 1862 | M26: 7
A27: BAF-6 | B27: ALFOMBRAS B-MATT AMAROK | C27: 186340 | D27: =C27*1.4 -> 260876 | E27: =D27-C27 -> 74536 | F27: 5 | G27: =D27*0.95 -> 247832.2 | H27: =D27*1.21 -> 315659.96 | J27: =C27*F27 -> 931700 | K27: =E27*F27 -> 372680 | L27: 145411 | M27: 0
A28: BAF-4 | B28: ALFOMBRAS B-MATT HILUX | C28: 186340 | D28: =C28*1.4 -> 260876 | E28: =D28-C28 -> 74536 | F28: 3 | G28: =D28*0.95 -> 247832.2 | H28: =D28*1.21 -> 315659.96 | J28: =C28*F28 -> 559020 | K28: =E28*F28 -> 223608 | L28: 145411 | M28: 1
A29: BAF-1 | B29: ALFOMBRAS B-MATT RANGER | C29: 186340 | D29: =C29*1.4 -> 260876 | E29: =D29-C29 -> 74536 | F29: 1 | G29: =D29*0.95 -> 247832.2 | H29: =D29*1.21 -> 315659.96 | J29: =C29*F29 -> 186340 | K29: =E29*F29 -> 74536 | L29: 145411 | M29: 0
A30: AB-50 | B30: AMORTIGUADOR LEVANTA CAPOT AMAROK | C30: =_xlfn.LET(_xlpm.x,_xlfn.XLOOKUP(ROW(),Ajustes!$A$5:$A$104,Ajustes!$D$5:$D$104,""),IF(_xlpm.x="",L30,_xlpm.x)) -> 139104 | D30: =C30*1.4 -> 194745.6 | E30: =D30-C30 -> 55641.6 | F30: =_xlfn.LET(_xlpm.x,_xlfn.XLOOKUP(ROW(),Ajustes!$A$5:$A$104,Ajustes!$E$5:$E$104,""),IF(_xlpm.x="",M30,_xlpm.x)) -> 2 | G30: =D30*0.95 -> 185008.32 | H30: =D30*1.21 -> 235642.18 | J30: =C30*F30 -> 278208 | K30: =E30*F30 -> 111283.2 | L30: 139104 | M30: 2
A31: AB-30 | B31: AMORTIGUADOR PORTON AMAROK S/ BARRA TORSION - IMPORTADO | C31: =_xlfn.LET(_xlpm.x,_xlfn.XLOOKUP(ROW(),Ajustes!$A$5:$A$104,Ajustes!$D$5:$D$104,""),IF(_xlpm.x="",L31,_xlpm.x)) -> 125850 | D31: =C31*1.4 -> 176190 | E31: =D31-C31 -> 50340 | F31: =_xlfn.LET(_xlpm.x,_xlfn.XLOOKUP(ROW(),Ajustes!$A$5:$A$104,Ajustes!$E$5:$E$104,""),IF(_xlpm.x="",M31,_xlpm.x)) -> 4 | G31: =D31*0.95 -> 167380.5 | H31: =D31*1.21 -> 213189.9 | J31: =C31*F31 -> 503400 | K31: =E31*F31 -> 201360 | L31: 125850 | M31: 4
A32: AB-31 | B32: AMORTIGUADOR PORTON CHEVROLET S-10 12+/24+ IMPORTADO | C32: 128464 | D32: =C32*1.4 -> 179849.6 | E32: =D32-C32 -> 51385.6 | F32: 1 | G32: =D32*0.95 -> 170857.12 | H32: =D32*1.21 -> 217618.02
A33: AB-38 | B33: AMORTIGUADOR PORTON FORD RANGER 23+ | C33: =_xlfn.LET(_xlpm.x,_xlfn.XLOOKUP(ROW(),Ajustes!$A$5:$A$104,Ajustes!$D$5:$D$104,""),IF(_xlpm.x="",L33,_xlpm.x)) -> 118734 | D33: =C33*1.4 -> 166227.6 | E33: =D33-C33 -> 47493.6 | F33: =_xlfn.LET(_xlpm.x,_xlfn.XLOOKUP(ROW(),Ajustes!$A$5:$A$104,Ajustes!$E$5:$E$104,""),IF(_xlpm.x="",M33,_xlpm.x)) -> 0 | G33: =D33*0.95 -> 157916.22 | H33: =D33*1.21 -> 201135.4 | J33: =C33*F33 -> 0 | K33: =E33*F33 -> 0 | L33: 118734 | M33: 0
A34: AB-32 | B34: AMORTIGUADOR PORTON TOYOTA HILUX 16+ - IMPORTADO (JUEGO) | C34: =_xlfn.LET(_xlpm.x,_xlfn.XLOOKUP(ROW(),Ajustes!$A$5:$A$104,Ajustes!$D$5:$D$104,""),IF(_xlpm.x="",L34,_xlpm.x)) -> 223781 | D34: =C34*1.4 -> 313293.4 | E34: =D34-C34 -> 89512.4 | F34: 0 | G34: =D34*0.95 -> 297628.73 | H34: =D34*1.21 -> 379085.01 | J34: =C34*F34 -> 0 | K34: =E34*F34 -> 0 | L34: 223781 | M34: 2
A35: K-27 | B35: ARO DE GOMA "ANTI-RUIDO" | C35: =_xlfn.LET(_xlpm.x,_xlfn.XLOOKUP(ROW(),Ajustes!$A$5:$A$104,Ajustes!$D$5:$D$104,""),IF(_xlpm.x="",L35,_xlpm.x)) -> 4279 | D35: =C35*1.4 -> 5990.6 | E35: =D35-C35 -> 1711.6 | F35: 28 | G35: =D35*0.95 -> 5691.07 | H35: =D35*1.21 -> 7248.626 | J35: =C35*F35 -> 119812 | K35: =E35*F35 -> 47924.8 | L35: 4279 | M35: 15
A36: B-30 | B36: BAR RACK ARCO REGULABLE UNIVERSAL | C36: =_xlfn.LET(_xlpm.x,_xlfn.XLOOKUP(ROW(),Ajustes!$A$5:$A$104,Ajustes!$D$5:$D$104,""),IF(_xlpm.x="",L36,_xlpm.x)) -> 251362 | D36: =C36*1.4 -> 351906.8 | E36: =D36-C36 -> 100544.8 | F36: 3 | G36: =D36*0.95 -> 334311.46 | H36: =D36*1.21 -> 425807.23 | K36: =E36*F36 -> 301634.4 | L36: 251362 | M36: 2
A37: BR-112 | B37: BARREROS DELANTEROS VW AMAROK 10+ (2 PIEZAS) | C37: =_xlfn.LET(_xlpm.x,_xlfn.XLOOKUP(ROW(),Ajustes!$A$5:$A$104,Ajustes!$D$5:$D$104,""),IF(_xlpm.x="",L37,_xlpm.x)) -> 55912 | D37: =C37*1.4 -> 78276.8 | E37: =D37-C37 -> 22364.8 | F37: 2 | G37: =D37*0.95 -> 74362.96 | H37: =D37*1.21 -> 94714.928 | J37: =C37*F37 -> 111824 | K37: =E37*F37 -> 44729.6 | L37: 55912
A38: BOX-370 | B38: BAUL DE TECHO PATAGONIA, CAPACIDAD 370 LITROS | C38: =_xlfn.LET(_xlpm.x,_xlfn.XLOOKUP(ROW(),Ajustes!$A$5:$A$104,Ajustes!$D$5:$D$104,""),IF(_xlpm.x="",L38,_xlpm.x)) -> 315366 | D38: =C38*1.4 -> 441512.4 | E38: =D38-C38 -> 126146.4 | F38: 0 | G38: =D38*0.95 -> 419436.78 | H38: =D38*1.21 -> 534230 | J38: =C38*F38 -> 0 | K38: =E38*F38 -> 0 | L38: 315366 | M38: 1
A39: BOX-16 | B39: BAUL LATERAL L.CONDUCTOR "EXPEDITION"-AGREGAR KIT | C39: =_xlfn.LET(_xlpm.x,_xlfn.XLOOKUP(ROW(),Ajustes!$A$5:$A$104,Ajustes!$D$5:$D$104,""),IF(_xlpm.x="",L39,_xlpm.x)) -> 341283 | D39: =C39*1.4 -> 477796.2 | E39: =D39-C39 -> 136513.2 | F39: =_xlfn.LET(_xlpm.x,_xlfn.XLOOKUP(ROW(),Ajustes!$A$5:$A$104,Ajustes!$E$5:$E$104,""),IF(_xlpm.x="",M39,_xlpm.x)) -> 1 | G39: =D39*0.95 -> 453906.39 | H39: =D39*1.21 -> 578133.4 | J39: =C39*F39 -> 341283 | K39: =E39*F39 -> 136513.2 | L39: 341283 | M39: 1
A40: BOX-40 | B40: BAUL METALICO "IRON-BOX" L95cm A48cm AL43cm 2 BOLSOS INTER. | C40: 482088 | D40: =C40*1.4 -> 674923.2 | E40: =D40-C40 -> 192835.2 | F40: 1 | G40: =D40*0.95 -> 641177.04 | H40: =D40*1.21 -> 816657.07 | J40: =C40*F40 -> 482088 | K40: =E40*F40 -> 192835.2 | L40: 445547 | M40: 0
A41: BOX-17 | B41: BAUL METALICO "IRON-BOX" LATERAL C/BOLSO | C41: =_xlfn.LET(_xlpm.x,_xlfn.XLOOKUP(ROW(),Ajustes!$A$5:$A$104,Ajustes!$D$5:$D$104,""),IF(_xlpm.x="",L41,_xlpm.x)) -> 272363 | D41: =C41*1.4 -> 381308.2 | E41: =D41-C41 -> 108945.2 | F41: =_xlfn.LET(_xlpm.x,_xlfn.XLOOKUP(ROW(),Ajustes!$A$5:$A$104,Ajustes!$E$5:$E$104,""),IF(_xlpm.x="",M41,_xlpm.x)) -> 1 | G41: =D41*0.95 -> 362242.79 | H41: =D41*1.21 -> 461382.92 | J41: =C41*F41 -> 272363 | K41: =E41*F41 -> 108945.2 | L41: 272363 | M41: 1
A42: BOX-4/5 | B42: BAUL PLAST."EXPEDICION" L. 97cm AN.55cm AL.45cm | C42: 445857 | D42: =C42*1.4 -> 624199.8 | E42: =D42-C42 -> 178342.8 | F42: 2 | G42: =D42*0.95 -> 592989.81 | H42: =D42*1.21 -> 755281.76 | J42: =C42*F42 -> 891714 | K42: =E42*F42 -> 356685.6 | L42: 420303 | M42: 1
A43: box-9/5 | B43: BAUL PLAST."EXPEDICION" L.130cm AN.55cm AL.45cm | C43: 620037 | D43: =C43*1.4 -> 868051.8 | E43: =D43-C43 -> 248014.8 | F43: 1 | G43: =D43*0.95 -> 824649.21 | H43: =D43*1.21 -> 1050342.7
A44: BOX-6/5 | B44: BAUL PLAST."EXPEDICION" L.140cm AN.55cm AL.45cm Base 98cm | C44: =_xlfn.LET(_xlpm.x,_xlfn.XLOOKUP(ROW(),Ajustes!$A$5:$A$104,Ajustes!$D$5:$D$104,""),IF(_xlpm.x="",L44,_xlpm.x)) -> 541472 | D44: =C44*1.4 -> 758060.8 | E44: =D44-C44 -> 216588.8 | F44: =_xlfn.LET(_xlpm.x,_xlfn.XLOOKUP(ROW(),Ajustes!$A$5:$A$104,Ajustes!$E$5:$E$104,""),IF(_xlpm.x="",M44,_xlpm.x)) -> 1 | G44: =D44*0.95 -> 720157.76 | H44: =D44*1.21 -> 917253.57 | J44: =C44*F44 -> 541472 | K44: =E44*F44 -> 216588.8 | L44: 541472 | M44: 1
A45: k-8/1 | B45: BOLITA CROMADA 1"7/8 VASTAGO 1" (2000 libras) | C45: =_xlfn.LET(_xlpm.x,_xlfn.XLOOKUP(ROW(),Ajustes!$A$5:$A$104,Ajustes!$D$5:$D$104,""),IF(_xlpm.x="",L45,_xlpm.x)) -> 19265 | D45: =C45*1.4 -> 26971 | E45: =D45-C45 -> 7706 | F45: 4 | G45: =D45*0.95 -> 25622.45 | H45: =D45*1.21 -> 32634.91 | J45: =C45*F45 -> 77060 | K45: =E45*F45 -> 30824 | L45: 19265 | M45: 6
A46: K-12/1 | B46: BOLITA CROMADA 2" VASTAGO 1" (3000 libras) | C46: =_xlfn.LET(_xlpm.x,_xlfn.XLOOKUP(ROW(),Ajustes!$A$5:$A$104,Ajustes!$D$5:$D$104,""),IF(_xlpm.x="",L46,_xlpm.x)) -> 22054 | D46: =C46*1.4 -> 30875.6 | E46: =D46-C46 -> 8821.6 | F46: =_xlfn.LET(_xlpm.x,_xlfn.XLOOKUP(ROW(),Ajustes!$A$5:$A$104,Ajustes!$E$5:$E$104,""),IF(_xlpm.x="",M46,_xlpm.x)) -> 3 | G46: =D46*0.95 -> 29331.82 | H46: =D46*1.21 -> 37359.476 | J46: =C46*F46 -> 66162 | K46: =E46*F46 -> 26464.8 | L46: 22054 | M46: 3
A47: K-8 | B47: BOLITA CROMADA 1" 7/8 VASTAGO 3/4 (2000 LIBRAS) | C47: =_xlfn.LET(_xlpm.x,_xlfn.XLOOKUP(ROW(),Ajustes!$A$5:$A$104,Ajustes!$D$5:$D$104,""),IF(_xlpm.x="",L47,_xlpm.x)) -> 15762 | D47: =C47*1.4 -> 22066.8 | E47: =D47-C47 -> 6304.8 | F47: 2 | G47: =D47*0.95 -> 20963.46 | H47: =D47*1.21 -> 26700.828 | J47: =C47*F47 -> 31524 | K47: =E47*F47 -> 12609.6 | L47: 15762 | M47: 1
A48: K-12 | B48: BOLITA CROMADA 2" VASTAGO 3/4 (3000 LIBRAS) | C48: =_xlfn.LET(_xlpm.x,_xlfn.XLOOKUP(ROW(),Ajustes!$A$5:$A$104,Ajustes!$D$5:$D$104,""),IF(_xlpm.x="",L48,_xlpm.x)) -> 18887 | D48: =C48*1.4 -> 26441.8 | E48: =D48-C48 -> 7554.8 | F48: =_xlfn.LET(_xlpm.x,_xlfn.XLOOKUP(ROW(),Ajustes!$A$5:$A$104,Ajustes!$E$5:$E$104,""),IF(_xlpm.x="",M48,_xlpm.x)) -> 0 | G48: =D48*0.95 -> 25119.71 | H48: =D48*1.21 -> 31994.578 | J48: =C48*F48 -> 0 | K48: =E48*F48 -> 0 | L48: 18887 | M48: 0
A49: BC-10 | B49: BOLSA PORTA CABEZAL TRACC | C49: =_xlfn.LET(_xlpm.x,_xlfn.XLOOKUP(ROW(),Ajustes!$A$5:$A$104,Ajustes!$D$5:$D$104,""),IF(_xlpm.x="",L49,_xlpm.x)) -> 3709 | D49: =C49*1.4 -> 5192.6 | E49: =D49-C49 -> 1483.6 | F49: =_xlfn.LET(_xlpm.x,_xlfn.XLOOKUP(ROW(),Ajustes!$A$5:$A$104,Ajustes!$E$5:$E$104,""),IF(_xlpm.x="",M49,_xlpm.x)) -> 2 | G49: =D49*0.95 -> 4932.97 | H49: =D49*1.21 -> 6283.046 | J49: =C49*F49 -> 7418 | K49: =E49*F49 -> 2967.2 | L49: 3709 | M49: 2
A50: BLS-1 | B50: BOLSO PARA CAJA DE CARGA ESTANCO UNIVERSAL (120X100X45CM) | C50: 134042 | D50: =C50*1.4 -> 187658.8 | E50: =D50-C50 -> 53616.8 | F50: 2 | G50: =D50*0.95 -> 178275.86 | H50: =D50*1.21 -> 227067.15
A51: BP-1 | B51: BURLETE PORTON AMAROK S-10 12+ HILUX 05-15 16+ FRONTIER 16+ | C51: =_xlfn.LET(_xlpm.x,_xlfn.XLOOKUP(ROW(),Ajustes!$A$5:$A$104,Ajustes!$D$5:$D$104,""),IF(_xlpm.x="",L51,_xlpm.x)) -> 55141 | D51: =C51*1.4 -> 77197.4 | E51: =D51-C51 -> 22056.4 | F51: 1 | G51: =D51*0.95 -> 73337.53 | H51: =D51*1.21 -> 93408.854 | J51: =C51*F51 -> 55141 | K51: =E51*F51 -> 22056.4 | L51: 55141 | M51: 2
A52: BAF-14 | B52: C.ALFOMBRAS B-MATT TOYOTA HILUX 05-15 D/C 3 PIEZAS | C52: 154252 | D52: =C52*1.4 -> 215952.8 | E52: =D52-C52 -> 61700.8 | F52: 1 | G52: =D52*0.95 -> 205155.16 | H52: =D52*1.21 -> 261302.89
A53: K-1 | B53: CABEZAL P/PERNO | C53: =_xlfn.LET(_xlpm.x,_xlfn.XLOOKUP(ROW(),Ajustes!$A$5:$A$104,Ajustes!$D$5:$D$104,""),IF(_xlpm.x="",L53,_xlpm.x)) -> 40001 | D53: =C53*1.4 -> 56001.4 | E53: =D53-C53 -> 16000.4 | F53: 2 | G53: =D53*0.95 -> 53201.33 | H53: =D53*1.21 -> 67761.694 | J53: =C53*F53 -> 80002 | K53: =E53*F53 -> 32000.8 | L53: 40001 | M53: 0
A54: K-3 | B54: CABEZAL ALTO P/PERNO | C54: 43282 | D54: =C54*1.4 -> 60594.8 | E54: =D54-C54 -> 17312.8 | F54: =_xlfn.LET(_xlpm.x,_xlfn.XLOOKUP(ROW(),Ajustes!$A$5:$A$104,Ajustes!$E$5:$E$104,""),IF(_xlpm.x="",M54,_xlpm.x)) -> 1 | G54: =D54*0.95 -> 57565.06 | H54: =D54*1.21 -> 73319.708 | J54: =C54*F54 -> 43282 | K54: =E54*F54 -> 17312.8 | L54: 42231 | M54: 1
A55: K-33 | B55: CABEZAL ALTO Y LARGO ESPECIAL P/PERNO | C55: =_xlfn.LET(_xlpm.x,_xlfn.XLOOKUP(ROW(),Ajustes!$A$5:$A$104,Ajustes!$D$5:$D$104,""),IF(_xlpm.x="",L55,_xlpm.x)) -> 50694 | D55: =C55*1.4 -> 70971.6 | E55: =D55-C55 -> 20277.6 | F55: =_xlfn.LET(_xlpm.x,_xlfn.XLOOKUP(ROW(),Ajustes!$A$5:$A$104,Ajustes!$E$5:$E$104,""),IF(_xlpm.x="",M55,_xlpm.x)) -> 1 | G55: =D55*0.95 -> 67423.02 | H55: =D55*1.21 -> 85875.636 | J55: =C55*F55 -> 50694 | K55: =E55*F55 -> 20277.6 | L55: 50694 | M55: 1
A56: K-23/3 | B56: CABEZAL FORD ORIG. P/PERNO (MAVERICK/RANGER/RAPT/F-150) | C56: 66876 | D56: =C56*1.4 -> 93626.4 | E56: =D56-C56 -> 26750.4 | F56: 2 | G56: =D56*0.95 -> 88945.08 | H56: =D56*1.21 -> 113287.94 | J56: =C56*F56 -> 133752 | K56: =E56*F56 -> 53500.8 | L56: 64304 | M56: 2
A57: K-23/1 | B57: CABEZAL MAXITRACC P/BOCHA K-8/1 (NO INCLUIDA) | C57: =_xlfn.LET(_xlpm.x,_xlfn.XLOOKUP(ROW(),Ajustes!$A$5:$A$104,Ajustes!$D$5:$D$104,""),IF(_xlpm.x="",L57,_xlpm.x)) -> 50052 | D57: =C57*1.4 -> 70072.8 | E57: =D57-C57 -> 20020.8 | F57: =_xlfn.LET(_xlpm.x,_xlfn.XLOOKUP(ROW(),Ajustes!$A$5:$A$104,Ajustes!$E$5:$E$104,""),IF(_xlpm.x="",M57,_xlpm.x)) -> 1 | G57: =D57*0.95 -> 66569.16 | H57: =D57*1.21 -> 84788.088 | J57: =C57*F57 -> 50052 | K57: =E57*F57 -> 20020.8 | L57: 50052 | M57: 1
A58: K-22 | B58: CABEZAL MAXITRACC P/PERNO | C58: =_xlfn.LET(_xlpm.x,_xlfn.XLOOKUP(ROW(),Ajustes!$A$5:$A$104,Ajustes!$D$5:$D$104,""),IF(_xlpm.x="",L58,_xlpm.x)) -> 63042 | D58: =C58*1.4 -> 88258.8 | E58: =D58-C58 -> 25216.8 | F58: 7 | G58: =D58*0.95 -> 83845.86 | H58: =D58*1.21 -> 106793.15 | J58: =C58*F58 -> 441294 | K58: =E58*F58 -> 176517.6 | L58: 63042 | M58: 8
A59: K-22-A/1 | B59: CABEZAL MAXITRACC P/PERNO "AMORTIGUADOR INTERNO" | C59: =_xlfn.LET(_xlpm.x,_xlfn.XLOOKUP(ROW(),Ajustes!$A$5:$A$104,Ajustes!$D$5:$D$104,""),IF(_xlpm.x="",L59,_xlpm.x)) -> 94978 | D59: =C59*1.4 -> 132969.2 | E59: =D59-C59 -> 37991.2 | F59: 8 | G59: =D59*0.95 -> 126320.74 | H59: =D59*1.21 -> 160892.73 | J59: =C59*F59 -> 759824 | K59: =E59*F59 -> 303929.6 | L59: 94978 | M59: 6
A60: K-35-A | B60: CABEZAL MAXITRACC ALTO Y LARG AMORT.INT P/BOCHA (NO INCLUIDA | C60: =_xlfn.LET(_xlpm.x,_xlfn.XLOOKUP(ROW(),Ajustes!$A$5:$A$104,Ajustes!$D$5:$D$104,""),IF(_xlpm.x="",L60,_xlpm.x)) -> 106192 | D60: =C60*1.4 -> 148668.8 | E60: =D60-C60 -> 42476.8 | F60: =_xlfn.LET(_xlpm.x,_xlfn.XLOOKUP(ROW(),Ajustes!$A$5:$A$104,Ajustes!$E$5:$E$104,""),IF(_xlpm.x="",M60,_xlpm.x)) -> 1 | G60: =D60*0.95 -> 141235.36 | H60: =D60*1.21 -> 179889.25 | J60: =C60*F60 -> 106192 | K60: =E60*F60 -> 42476.8 | L60: 106192 | M60: 1
A61: K-42 | B61: CABEZAL MAXITRACC ALTO Y LARGO ESPECIAL PERNO | C61: =_xlfn.LET(_xlpm.x,_xlfn.XLOOKUP(ROW(),Ajustes!$A$5:$A$104,Ajustes!$D$5:$D$104,""),IF(_xlpm.x="",L61,_xlpm.x)) -> 77473 | D61: =C61*1.4 -> 108462.2 | E61: =D61-C61 -> 30989.2 | F61: =_xlfn.LET(_xlpm.x,_xlfn.XLOOKUP(ROW(),Ajustes!$A$5:$A$104,Ajustes!$E$5:$E$104,""),IF(_xlpm.x="",M61,_xlpm.x)) -> 1 | G61: =D61*0.95 -> 103039.09 | H61: =D61*1.21 -> 131239.26 | J61: =C61*F61 -> 77473 | K61: =E61*F61 -> 30989.2 | L61: 77473 | M61: 1
...

Sheet FILTROS
A2: BUSCAR =
A3: {=IF(B1="","",_xlfn.LET(_xlpm.coincide,_xlfn.LAMBDA(_xlpm.t,_xlpm.p,OR(ISNUMBER(SEARCH(_xlpm.t,_xlpm.p)),OR(_xlfn.MAP(_xlfn.SEQUENCE(LEN(_xlpm.t)+1,,0),_xlfn.LAMBDA(_xlpm.k,ISNUMBER(SEARCH(LEFT(_xlpm.t,_xlpm.k)&"?"&MID(_xlpm.t,_xlpm.k+1,LEN(_xlpm.t)),_xlpm.p))))),OR(_xlfn.MAP(_xlfn.SEQUENCE(LEN(_xlpm.t)),_xlfn.LAMBDA(_xlpm.k,ISNUMBER(SEARCH(REPLACE(_xlpm.t,_xlpm.k,1,"?"),_xlpm.p))))),IF(LEN(_xlpm.t)>3,OR(_xlfn.MAP(_xlfn.SEQUENCE(LEN(_xlpm.t)),_xlfn.LAMBDA(_xlpm.k,ISNUMBER(SEARCH(REPLACE(_xlpm.t,_xlpm.k,1,""),_xlpm.p))))),FALSE))),_xlpm.terminos,_xlfn.TOCOL(_xlfn.TEXTSPLIT(LOWER(TRIM(B1))," "),1),_xlpm.productos,LOWER($B$27:$B$884),_xlpm.puntaje,_xlfn.BYROW(_xlpm.productos,_xlfn.LAMBDA(_xlpm.p,SUM(_xlfn.MAP(_xlpm.terminos,_xlfn.LAMBDA(_xlpm.t,--_xlpm.coincide(_xlpm.t,_xlpm.p)))))),_xlpm.datos,_xlfn.HSTACK($A$27:$H$884,ROW($B$27:$B$884)),IFERROR(_xlfn.TAKE(_xlfn._xlws.FILTER(_xlpm.datos,(_xlpm.puntaje=ROWS(_xlpm.terminos))*($B$27:$B$884<>"")),20),"NO ENCONTRADO")))}
A4: CODIGO | B4: PRODUCTO | C4: FABRICA | D4: PUBLICO | E4: GANANCIA | F4: STOCK | G4: DESC. 5 % | H4: IVA 21 %
A5: 3165141146950 | B5: FILTRO DE NAFTA BOSCH MOTOS HONDA BIZ CG YAMAHA CRIPTON ZANELLA | C5: 4472 | D5: =C5*1.4 -> 6260.8 | E5: =D5-C5 -> 1788.8 | F5: 20 | G5: =D5*0.95 -> 5947.76 | H5: =D5*1.21 -> 7575.568
A6: 7799076006254 | B6: KIT FILTROS VOLSKWAGEN SURAN/FOX 1,6 MSI (15/25) | D6: =C6*1.4 -> 0 | E6: =D6-C6 -> 0 | F6: 14 | G6: =D6*0.95 -> 0 | H6: =D6*1.21 -> 0
A7: 7798186475806 | B7: KIT FILTROS VOLSKWAGEN SURAN/FOX/GOL TREND/VOYAGE 1,6 8V | D7: =C7*1.4 -> 0 | E7: =D7-C7 -> 0 | F7: 10 | G7: =D7*0.95 -> 0 | H7: =D7*1.21 -> 0
A8: 7799076010442 | B8: KIT FILTROS VOLSKWAGEN POLO/VIRTUS/TCROSS 1,6 MSI 117 Cv(17/18) | D8: =C8*1.4 -> 0 | E8: =D8-C8 -> 0 | F8: 6 | G8: =D8*0.95 -> 0 | H8: =D8*1.21 -> 0
A9: 7799076004564 | B9: KIT FILTROS VOLSKGAWEN GOL 1,6 8V 1997+ | D9: =C9*1.4 -> 0 | E9: =D9-C9 -> 0 | F9: 1 | G9: =D9*0.95 -> 0 | H9: =D9*1.21 -> 0
A10: 171174073318 | B10: KIT FILTROS VOLSKGAWEN SURAN/GOL/FOX/SAVEIRO 1,6 8V | D10: =C10*1.4 -> 0 | E10: =D10-C10 -> 0 | F10: 1 | G10: =D10*0.95 -> 0 | H10: =D10*1.21 -> 0
A11: 7798186477152 | B11: KIT FILTROS VOLSKWAGEN VENTO 2.5 2006 + | D11: =C11*1.4 -> 0 | E11: =D11-C11 -> 0 | F11: 4 | G11: =D11*0.95 -> 0 | H11: =D11*1.21 -> 0
A12: 7799076004014 | B12: KIT FILTROS VOLSKWAGEN UP! 1,0 75 CV MPI | D12: =C12*1.4 -> 0 | E12: =D12-C12 -> 0 | F12: 14 | G12: =D12*0.95 -> 0 | H12: =D12*1.21 -> 0
A13: 7799076005691 | B13: KIT FILTROS NISSAN FRONTIER NACIONAL 2018 + | D13: =C13*1.4 -> 0 | E13: =D13-C13 -> 0 | F13: 5 | G13: =D13*0.95 -> 0 | H13: =D13*1.21 -> 0
A14: 7798186479538 | B14: KIT FILTROS FIAT PALIO/SIENA/IDEA/SATRADA 1,6 ETORQ 2011+ | D14: =C14*1.4 -> 0 | E14: =D14-C14 -> 0 | F14: 2 | G14: =D14*0.95 -> 0 | H14: =D14*1.21 -> 0
A15: 7798186479347 | B15: KIT FILTROS FIAT TORO 2,0 16 V MULTIJET 2016+ | D15: =C15*1.4 -> 0 | E15: =D15-C15 -> 0 | F15: 7 | G15: =D15*0.95 -> 0 | H15: =D15*1.21 -> 0
A16: 7799076003345 | B16: KIT FILTROS JEEP RENEGADE/FIAT TORO NAFTA 1,8 16V 2016 + | D16: =C16*1.4 -> 0 | E16: =D16-C16 -> 0 | F16: 2 | G16: =D16*0.95 -> 0 | H16: =D16*1.21 -> 0
A17: 7798186475776 | B17: KIT FILTROS FIAT UNO WAY | D17: =C17*1.4 -> 0 | E17: =D17-C17 -> 0 | F17: 2 | G17: =D17*0.95 -> 0 | H17: =D17*1.21 -> 0
... A77: 171174073542 | B77: KIT FILTROS CHEVROLET S10 2.4 2.5 2.8 DURAMAS MWM 12+ | D77: =C77*1.4 -> 0 | E77: =D77-C77 -> 0 | F77: 7 | G77: =D77*0.95 -> 0 | H77: =D77*1.21 -> 0
D78: =C78*1.4 -> 0 | E78: =D78-C78 -> 0 | G78: =D78*0.95 -> 0 | H78: =D78*1.21 -> 0
D79: =C79*1.4 -> 0 | E79: =D79-C79 -> 0 | G79: =D79*0.95 -> 0 | H79: =D79*1.21 -> 0
D80: =C80*1.4 -> 0 | E80: =D80-C80 -> 0 | G80: =D80*0.95 -> 0 | H80: =D80*1.21 -> 0
D81: =C81*1.4 -> 0 | E81: =D81-C81 -> 0 | G81: =D81*0.95 -> 0 | H81: =D81*1.21 -> 0
D82: =C82*1.4 -> 0 | E82: =D82-C82 -> 0 | G82: =D82*0.95 -> 0 | H82: =D82*1.21 -> 0
D83: =C83*1.4 -> 0 | E83: =D83-C83 -> 0 | G83: =D83*0.95 -> 0 | H83: =D83*1.21 -> 0
D84: =C84*1.4 -> 0 | E84: =D84-C84 -> 0 | G84: =D84*0.95 -> 0 | H84: =D84*1.21 -> 0
D85: =C85*1.4 -> 0 | E85: =D85-C85 -> 0 | G85: =D85*0.95 -> 0 | H85: =D85*1.21 -> 0
D86: =C86*1.4 -> 0 | E86: =D86-C86 -> 0 | G86: =D86*0.95 -> 0 | H86: =D86*1.21 -> 0
D87: =C87*1.4 -> 0 | E87: =D87-C87 -> 0 | G87: =D87*0.95 -> 0 | H87: =D87*1.21 -> 0
D88: =C88*1.4 -> 0 | E88: =D88-C88 -> 0 | G88: =D88*0.95 -> 0 | H88: =D88*1.21 -> 0
D89: =C89*1.4 -> 0 | E89: =D89-C89 -> 0 | G89: =D89*0.95 -> 0 | H89: =D89*1.21 -> 0
... D490: =C490*1.4 -> 0 | E490: =D490-C490 -> 0 | G490: =D490*0.95 -> 0 | H490: =D490*1.21 -> 0
D491: =C491*1.4 -> 0 | E491: =D491-C491 -> 0 | G491: =D491*0.95 -> 0 | H491: =D491*1.21 -> 0 | I491: =D490*F490 -> 0
D492: =C492*1.4 -> 0 | E492: =D492-C492 -> 0 | G492: =D492*0.95 -> 0 | H492: =D492*1.21 -> 0 | I492: =D491*F491 -> 0
D493: =C493*1.4 -> 0 | E493: =D493-C493 -> 0 | G493: =D493*0.95 -> 0 | H493: =D493*1.21 -> 0 | I493: =D492*F492 -> 0
D494: =C494*1.4 -> 0 | E494: =D494-C494 -> 0 | G494: =D494*0.95 -> 0 | H494: =D494*1.21 -> 0 | I494: =D493*F493 -> 0
D495: =C495*1.4 -> 0 | E495: =D495-C495 -> 0 | G495: =D495*0.95 -> 0 | H495: =D495*1.21 -> 0 | I495: =D494*F494 -> 0
D496: =C496*1.4 -> 0 | E496: =D496-C496 -> 0 | G496: =D496*0.95 -> 0 | H496: =D496*1.21 -> 0 | I496: =D495*F495 -> 0
D497: =C497*1.4 -> 0 | E497: =D497-C497 -> 0 | G497: =D497*0.95 -> 0 | H497: =D497*1.21 -> 0 | I497: =D496*F496 -> 0
D498: =C498*1.4 -> 0 | E498: =D498-C498 -> 0 | G498: =D498*0.95 -> 0 | H498: =D498*1.21 -> 0 | I498: =D497*F497 -> 0
D499: =C499*1.4 -> 0 | E499: =D499-C499 -> 0 | G499: =D499*0.95 -> 0 | H499: =D499*1.21 -> 0 | I499: =D498*F498 -> 0
D500: =C500*1.4 -> 0 | E500: =D500-C500 -> 0 | G500: =D500*0.95 -> 0 | H500: =D500*1.21 -> 0 | I500: =D499*F499 -> 0
...

Sheet norte
A1: {=_xlfn._xlws.FILTER(A5:H141,ISNUMBER(SEARCH(B2,A5:A141)))} -> #VALUE!
A2: BUSCAR =
A4: CODIGO | B4: PRODUCTO | C4: FABRICA | D4: PUBLICO | E4: GANANCIA | F4: STOCK | G4: DESC. 5 % | H4: IVA 21 %
A5: 7794004953938 | B5: CINTA AISLADORA | C5: 1704 | D5: =C5*1.4 -> 2385.6 | E5: =D5-C5 -> 681.6 | F5: 10 | G5: =D5*0.95 -> 2266.32 | H5: =D5*1.21 -> 2886.576
A6: 7792993001616 | B6: CABLE PUENTE 120 AMP 2,3 MTS | C6: 8973 | D6: =C6*1.4 -> 12562.2 | E6: =D6-C6 -> 3589.2 | F6: 2 | G6: =D6*0.95 -> 11934.09 | H6: =D6*1.21 -> 15200.262
A7: 17798090229967 | B7: LAVAPARABRISAS CONCENTRADO | C7: 1830 | D7: =C7*1.4 -> 2562 | E7: =D7-C7 -> 732 | F7: 24 | G7: =D7*0.95 -> 2433.9 | H7: =D7*1.21 -> 3100.02
A8: 7799064056407 | B8: CALCOS REGLAMENTARIAS | C8: 8094 | D8: =C8*1.4 -> 11331.6 | E8: =D8-C8 -> 3237.6 | F8: 6 | G8: =D8*0.95 -> 10765.02 | H8: =D8*1.21 -> 13711.236
A9: 7799064056469 | B9: CINTA REGLAMENTARIA X 1M INTERNACIONAL | C9: 5706 | D9: =C9*1.4 -> 7988.4 | E9: =D9-C9 -> 2282.4 | F9: 1 | G9: =D9*0.95 -> 7588.98 | H9: =D9*1.21 -> 9665.964
A10: 7799064056445 | B10: CINTA REGLAMENTARIA X 0,5 CEBRADA | C10: 4734 | D10: =C10*1.4 -> 6627.6 | E10: =D10-C10 -> 1893.6 | F10: 1 | G10: =D10*0.95 -> 6296.22 | H10: =D10*1.21 -> 8019.396
A11: 7794287000015 | B11: MATAFUEGO MELISAM POLVO 1 KILO | C11: 35117 | D11: =C11*1.4 -> 49163.8 | E11: =D11-C11 -> 14046.8 | F11: 2 | G11: =D11*0.95 -> 46705.61 | H11: =D11*1.21 -> 59488.198
A12: 7798090227119 | B12: INFLA Y SELLA FIXIT | C12: 13375 | D12: =C12*1.4 -> 18725 | E12: =D12-C12 -> 5350 | F12: 6 | G12: =D12*0.95 -> 17788.75 | H12: =D12*1.21 -> 22657.25
A13: 7798090220318 | B13: LIQUIDO DE FRENO WANDER TIPO 3 200CC | C13: 2993 | D13: =C13*1.4 -> 4190.2 | E13: =D13-C13 -> 1197.2 | F13: 24 | G13: =D13*0.95 -> 3980.69 | H13: =D13*1.21 -> 5070.142
A14: 7798121761193 | B14: BOTIQUIN PRIMEROS AUXILIOS | C14: 8489 | D14: =C14*1.4 -> 11884.6 | E14: =D14-C14 -> 3395.6 | F14: 2 | G14: =D14*0.95 -> 11290.37 | H14: =D14*1.21 -> 14380.366
A15: 7798090220035 | B15: AGUA DESMINERALIZADA X 5 LITROS | C15: 3057 | D15: =C15*1.4 -> 4279.8 | E15: =D15-C15 -> 1222.8 | F15: 24 | G15: =D15*0.95 -> 4065.81 | H15: =D15*1.21 -> 5178.558
A16: 7798058467601 | B16: ARRANCA MOTORES LOCX | C16: 12316 | D16: =C16*1.4 -> 17242.4 | E16: =D16-C16 -> 4926.4 | F16: 19 | G16: =D16*0.95 -> 16380.28 | H16: =D16*1.21 -> 20863.304
... A23: 267 | B23: CRIQUET HIDRAULICO CARRITO 2T | C23: 53766 | D23: =C23*1.4 -> 75272.4 | E23: =D23-C23 -> 21506.4 | F23: 1 | G23: =D23*0.95 -> 71508.78 | H23: =D23*1.21 -> 91079.604
D24: =C24*1.4 -> 0 | E24: =D24-C24 -> 0 | G24: =D24*0.95 -> 0 | H24: =D24*1.21 -> 0
D25: =C25*1.4 -> 0 | E25: =D25-C25 -> 0 | G25: =D25*0.95 -> 0 | H25: =D25*1.21 -> 0
D26: =C26*1.4 -> 0 | E26: =D26-C26 -> 0 | G26: =D26*0.95 -> 0 | H26: =D26*1.21 -> 0
D27: =C27*1.4 -> 0 | E27: =D27-C27 -> 0 | G27: =D27*0.95 -> 0 | H27: =D27*1.21 -> 0
D28: =C28*1.4 -> 0 | E28: =D28-C28 -> 0 | G28: =D28*0.95 -> 0 | H28: =D28*1.21 -> 0
D29: =C29*1.4 -> 0 | E29: =D29-C29 -> 0 | G29: =D29*0.95 -> 0 | H29: =D29*1.21 -> 0
D30: =C30*1.4 -> 0 | E30: =D30-C30 -> 0 | G30: =D30*0.95 -> 0 | H30: =D30*1.21 -> 0
D31: =C31*1.4 -> 0 | E31: =D31-C31 -> 0 | G31: =D31*0.95 -> 0 | H31: =D31*1.21 -> 0
D32: =C32*1.4 -> 0 | E32: =D32-C32 -> 0 | G32: =D32*0.95 -> 0 | H32: =D32*1.21 -> 0
D33: =C33*1.4 -> 0 | E33: =D33-C33 -> 0 | G33: =D33*0.95 -> 0 | H33: =D33*1.21 -> 0
D34: =C34*1.4 -> 0 | E34: =D34-C34 -> 0 | G34: =D34*0.95 -> 0 | H34: =D34*1.21 -> 0
D35: =C35*1.4 -> 0 | E35: =D35-C35 -> 0 | G35: =D35*0.95 -> 0 | H35: =D35*1.21 -> 0
... D495: =C495*1.4 -> 0 | E495: =D495-C495 -> 0 | G495: =D495*0.95 -> 0 | H495: =D495*1.21 -> 0
D496: =C496*1.4 -> 0 | E496: =D496-C496 -> 0 | G496: =D496*0.95 -> 0 | H496: =D496*1.21 -> 0 | I496: =D495*F495 -> 0
D497: =C497*1.4 -> 0 | E497: =D497-C497 -> 0 | G497: =D497*0.95 -> 0 | H497: =D497*1.21 -> 0 | I497: =D496*F496 -> 0
D498: =C498*1.4 -> 0 | E498: =D498-C498 -> 0 | G498: =D498*0.95 -> 0 | H498: =D498*1.21 -> 0 | I498: =D497*F497 -> 0
D499: =C499*1.4 -> 0 | E499: =D499-C499 -> 0 | G499: =D499*0.95 -> 0 | H499: =D499*1.21 -> 0 | I499: =D498*F498 -> 0
D500: =C500*1.4 -> 0 | E500: =D500-C500 -> 0 | G500: =D500*0.95 -> 0 | H500: =D500*1.21 -> 0 | I500: =D499*F499 -> 0
D501: =C501*1.4 -> 0 | E501: =D501-C501 -> 0 | G501: =D501*0.95 -> 0 | H501: =D501*1.21 -> 0 | I501: =D500*F500 -> 0
D502: =C502*1.4 -> 0 | E502: =D502-C502 -> 0 | G502: =D502*0.95 -> 0 | H502: =D502*1.21 -> 0 | I502: =D501*F501 -> 0
D503: =C503*1.4 -> 0 | E503: =D503-C503 -> 0 | G503: =D503*0.95 -> 0 | H503: =D503*1.21 -> 0 | I503: =D502*F502 -> 0
D504: =C504*1.4 -> 0 | E504: =D504-C504 -> 0 | G504: =D504*0.95 -> 0 | H504: =D504*1.21 -> 0 | I504: =D503*F503 -> 0
D505: =C505*1.4 -> 0 | E505: =D505-C505 -> 0 | G505: =D505*0.95 -> 0 | H505: =D505*1.21 -> 0 | I505: =D504*F504 -> 0
D506: =C506*1.4 -> 0 | E506: =D506-C506 -> 0 | G506: =D506*0.95 -> 0 | H506: =D506*1.21 -> 0 | I506: =D505*F505 -> 0
...

Sheet big toys
A1: {=_xlfn._xlws.FILTER(A5:H145,ISNUMBER(SEARCH(B2,A5:A145)))} -> #VALUE!
A2: BUSCAR =
E3: Precios con iva venta al publico
A4: CODIGO | B4: PRODUCTO | C4: FABRICA | D4: PUBLICO | E4: GANANCIA | F4: STOCK | G4: DESC. 5 % | H4: IVA 21 %
A5: LTG-AM-001 | B5: AMORTIGUADOR PORTON AMAROK | C5: 63750 | D5: =C5*1.4 -> 89250 | E5: =D5-C5 -> 25500 | F5: 2 | G5: =D5*0.95 -> 84787.5 | H5: =D5*1.21 -> 107992.5
A6: LSPR-001 | B6: AMORTIGUADOR CAPOT HILUX/ SW4 2016-2022 | C6: 73440 | D6: =C6*1.4 -> 102816 | E6: =D6-C6 -> 29376 | F6: 1 | G6: =D6*0.95 -> 97675.2 | H6: =D6*1.21 -> 124407.36
A7: LTY-025-EXT | B7: SENSOR PRESION NEUMATICO DIGITAL | C7: 60480 | D7: =C7*1.4 -> 84672 | E7: =D7-C7 -> 24192 | F7: 3 | G7: =D7*0.95 -> 80438.4 | H7: =D7*1.21 -> 102453.12
A8: LPW-003 | B8: SOPORTES STARLINK P/ VIDRIO 4 VENTOSAS | C8: 45000 | D8: =C8*1.4 -> 63000 | E8: =D8-C8 -> 18000 | F8: 2 | G8: =D8*0.95 -> 59850 | H8: =D8*1.21 -> 76230
A9: RE21-013 | B9: FENDERS HILUX 2021 | C9: 297500 | D9: =C9*1.4 -> 416500 | E9: =D9-C9 -> 119000 | F9: 1 | G9: =D9*0.95 -> 395675 | H9: =D9*1.21 -> 503965
A10: LG-002 | B10: LUCES LED KIT X4 | C10: 15530 | D10: =C10*1.4 -> 21742 | E10: =D10-C10 -> 6212 | F10: 8 | G10: =D10*0.95 -> 20654.9 | H10: =D10*1.21 -> 26307.82
A11: LPS-010 | B11: SOPAPA VACIO 75MM DIAMETRO | C11: 50490 | D11: =C11*1.4 -> 70686 | E11: =D11-C11 -> 20196 | F11: 2 | G11: =D11*0.95 -> 67151.7 | H11: =D11*1.21 -> 85530.06
A12: 6W037 | B12: SEPARADOR RUEDA BTX HILUX/ SW4/ DAKOTA/ TITANO 6X139 32MM | C12: 53192 | D12: =C12*1.4 -> 74468.8 | E12: =D12-C12 -> 21276.8 | F12: 4 | G12: =D12*0.95 -> 70745.36 | H12: =D12*1.21 -> 90107.248
A13: 5W074 | B13: SEPARADOR RUEDA BTX AMAROK 5X120 38MM X UNIDAD | C13: 51229 | D13: =C13*1.4 -> 71720.6 | E13: =D13-C13 -> 20491.6 | F13: 8 | G13: =D13*0.95 -> 68134.57 | H13: =D13*1.21 -> 86781.926
A14: IV001 | B14: INVERTER 500W | C14: 55539 | D14: =C14*1.4 -> 77754.6 | E14: =D14-C14 -> 22215.6 | F14: 1 | G14: =D14*0.95 -> 73866.87 | H14: =D14*1.21 -> 94083.066
A15: 15361+LPS-011 | B15: SOPORTES ANT. STARLINK (CASE) +4 BASE IMANTADA 80MM DIAM. | C15: 146913 | D15: =C15*1.4 -> 205678.2 | E15: =D15-C15 -> 58765.2 | F15: 3 | G15: =D15*0.95 -> 195394.29 | H15: =D15*1.21 -> 248870.62
A16: 15361 | B16: SOPORTES ANTENA STARLINK (CASE) | C16: 84793 | D16: =C16*1.4 -> 118710.2 | E16: =D16-C16 -> 33917.2 | F16: 3 | G16: =D16*0.95 -> 112774.69 | H16: =D16*1.21 -> 143639.34
A17: LPS-011 | B17: BASE IMANTADA 80MM DIAMETRO X UNIDAD | C17: 15530 | D17: =C17*1.4 -> 21742 | E17: =D17-C17 -> 6212 | F17: 12 | G17: =D17*0.95 -> 20654.9 | H17: =D17*1.21 -> 26307.82
A18: 6W053 | B18: SEPARADOR DE RUEDAS RANGER 6X139 38MM | C18: 54763 | D18: =C18*1.4 -> 76668.2 | E18: =D18-C18 -> 21905.2 | F18: 4 | G18: =D18*0.95 -> 72834.79 | H18: =D18*1.21 -> 92768.522
A19: L9 | B19: AMORTIGUADOR DE PORTON RANGER 23+ | C19: 72710 | D19: =C19*1.4 -> 101794 | E19: =D19-C19 -> 29084 | F19: 1 | G19: =D19*0.95 -> 96704.3 | H19: =D19*1.21 -> 123170.74
B20: STARLINK | C20: 180000 | D20: =C20*1.4 -> 252000 | E20: =D20-C20 -> 72000 | F20: 3 | G20: =D20*0.95 -> 239400 | H20: =D20*1.21 -> 304920
D21: =C21*1.4 -> 0 | E21: =D21-C21 -> 0 | G21: =D21*0.95 -> 0 | H21: =D21*1.21 -> 0
D22: =C22*1.4 -> 0 | E22: =D22-C22 -> 0 | G22: =D22*0.95 -> 0 | H22: =D22*1.21 -> 0
D23: =C23*1.4 -> 0 | E23: =D23-C23 -> 0 | G23: =D23*0.95 -> 0 | H23: =D23*1.21 -> 0
D24: =C24*1.4 -> 0 | E24: =D24-C24 -> 0 | G24: =D24*0.95 -> 0 | H24: =D24*1.21 -> 0
D25: =C25*1.4 -> 0 | E25: =D25-C25 -> 0 | G25: =D25*0.95 -> 0 | H25: =D25*1.21 -> 0
D26: =C26*1.4 -> 0 | E26: =D26-C26 -> 0 | G26: =D26*0.95 -> 0 | H26: =D26*1.21 -> 0
D27: =C27*1.4 -> 0 | E27: =D27-C27 -> 0 | G27: =D27*0.95 -> 0 | H27: =D27*1.21 -> 0
D28: =C28*1.4 -> 0 | E28: =D28-C28 -> 0 | G28: =D28*0.95 -> 0 | H28: =D28*1.21 -> 0
D29: =C29*1.4 -> 0 | E29: =D29-C29 -> 0 | G29: =D29*0.95 -> 0 | H29: =D29*1.21 -> 0
D30: =C30*1.4 -> 0 | E30: =D30-C30 -> 0 | G30: =D30*0.95 -> 0 | H30: =D30*1.21 -> 0
D31: =C31*1.4 -> 0 | E31: =D31-C31 -> 0 | G31: =D31*0.95 -> 0 | H31: =D31*1.21 -> 0
D32: =C32*1.4 -> 0 | E32: =D32-C32 -> 0 | G32: =D32*0.95 -> 0 | H32: =D32*1.21 -> 0
... D494: =C494*1.4 -> 0 | E494: =D494-C494 -> 0 | G494: =D494*0.95 -> 0 | H494: =D494*1.21 -> 0
D495: =C495*1.4 -> 0 | E495: =D495-C495 -> 0 | G495: =D495*0.95 -> 0 | H495: =D495*1.21 -> 0 | I495: =D494*F494 -> 0
D496: =C496*1.4 -> 0 | E496: =D496-C496 -> 0 | G496: =D496*0.95 -> 0 | H496: =D496*1.21 -> 0 | I496: =D495*F495 -> 0
D497: =C497*1.4 -> 0 | E497: =D497-C497 -> 0 | G497: =D497*0.95 -> 0 | H497: =D497*1.21 -> 0 | I497: =D496*F496 -> 0
D498: =C498*1.4 -> 0 | E498: =D498-C498 -> 0 | G498: =D498*0.95 -> 0 | H498: =D498*1.21 -> 0 | I498: =D497*F497 -> 0
D499: =C499*1.4 -> 0 | E499: =D499-C499 -> 0 | G499: =D499*0.95 -> 0 | H499: =D499*1.21 -> 0 | I499: =D498*F498 -> 0
D500: =C500*1.4 -> 0 | E500: =D500-C500 -> 0 | G500: =D500*0.95 -> 0 | H500: =D500*1.21 -> 0 | I500: =D499*F499 -> 0
D501: =C501*1.4 -> 0 | E501: =D501-C501 -> 0 | G501: =D501*0.95 -> 0 | H501: =D501*1.21 -> 0 | I501: =D500*F500 -> 0
...

Sheet Luces led
A1: {=_xlfn._xlws.FILTER(A5:H147,ISNUMBER(SEARCH(B2,A5:A147)))} -> #VALUE!
A2: BUSCAR =
A4: CODIGO | B4: PRODUCTO | C4: FABRICA | D4: PUBLICO | E4: GANANCIA | F4: STOCK | G4: DESC. 5 % | H4: IVA 21 %
A5: 661094211330 | B5: BARRA LED CURVA 180 WATTS BLANCA | C5: 60000 | E5: =D5-C5 -> -60000 | F5: 2 | G5: =D5*0.95 -> 0 | H5: =D5*1.21 -> 0
A6: 661094207463 | B6: BARRA LED CURVA 120 WATTS BLANCA | D6: =C6*1.4 -> 0 | E6: =D6-C6 -> 0 | G6: =D6*0.95 -> 0 | H6: =D6*1.21 -> 0
A7: 661094211286 | B7: BARRA LED RECTA 180 WATTS BLANCA | C7: 60000 | D7: =C7*1.4 -> 84000 | E7: =D7-C7 -> 24000 | F7: 2 | G7: =D7*0.95 -> 79800 | H7: =D7*1.21 -> 101640
B8: SNORKEL FORD RANGER | C8: 140000 | D8: =C8*1.4 -> 196000 | E8: =D8-C8 -> 56000 | F8: 2 | G8: =D8*0.95 -> 186200 | H8: =D8*1.21 -> 237160
B9: SNORKEL TOYOTA HILUX | C9: 140000 | D9: =C9*1.4 -> 196000 | E9: =D9-C9 -> 56000 | F9: 1 | G9: =D9*0.95 -> 186200 | H9: =D9*1.21 -> 237160
A10: 661094210913 | B10: BARRA LED RECTA 120 WATTS 52 CM | C10: 51000 | D10: =C10*1.4 -> 71400 | E10: =D10-C10 -> 20400 | F10: 1 | G10: =D10*0.95 -> 67830 | H10: =D10*1.21 -> 86394
A11: 661094207463 | B11: BARRA LED CURVA 120 WATTS BLANCA 52 CM | C11: 51000 | D11: =C11*1.4 -> 71400 | E11: =D11-C11 -> 20400 | F11: 1 | G11: =D11*0.95 -> 67830 | H11: =D11*1.21 -> 86394
A12: 661094222473 | B12: FARO LED REDONDO 12V 96 WATTS | C12: 15000 | D12: =C12*1.4 -> 21000 | E12: =D12-C12 -> 6000 | F12: 4 | G12: =D12*0.95 -> 19950 | H12: =D12*1.21 -> 25410
A13: 661094206961 | B13: FARO LED REDONDO 9V 27 WATTS | C13: 10000 | D13: =C13*1.4 -> 14000 | E13: =D13-C13 -> 4000 | F13: 3 | G13: =D13*0.95 -> 13300 | H13: =D13*1.21 -> 16940
B14: BARRA LED CUADRADA CHICA | C14: 20000 | D14: =C14*1.4 -> 28000 | E14: =D14-C14 -> 8000 | F14: 3 | G14: =D14*0.95 -> 26600 | H14: =D14*1.21 -> 33880
A15: 661094216533 | B15: Kit Cree Led H15 Canbus Alta Diurna Ranger/amarok V6/cruze | C15: 85000 | D15: =C15*1.4 -> 119000 | E15: =D15-C15 -> 34000 | F15: 3 | G15: =D15*0.95 -> 113050 | H15: =D15*1.21 -> 143990
A16: 661094212184 | B16: Kit Cree Led H4 S6 Pesados 22000lm 24v Heavy Duty Camiones | C16: 22000 | D16: =C16*1.4 -> 30800 | E16: =D16-C16 -> 8800 | F16: 7 | G16: =D16*0.95 -> 29260 | H16: =D16*1.21 -> 37268
A17: 661094215512 | B17: Kit Cree Led C6 Mini 12v H11 | C17: 8000 | D17: =C17*1.4 -> 11200 | E17: =D17-C17 -> 3200 | F17: 6 | G17: =D17*0.95 -> 10640 | H17: =D17*1.21 -> 13552
A18: 661094215499 | B18: Kit Cree Led C6 Mini 12v H7 | C18: 8000 | D18: =C18*1.4 -> 11200 | E18: =D18-C18 -> 3200 | F18: 2 | G18: =D18*0.95 -> 10640 | H18: =D18*1.21 -> 13552
A19: 661094215505 | B19: Kit Cree Led C6 Mini 12v H1 | C19: 8000 | D19: =C19*1.4 -> 11200 | E19: =D19-C19 -> 3200 | F19: 4 | G19: =D19*0.95 -> 10640 | H19: =D19*1.21 -> 13552
A20: 661094215536 | B20: Kit Cree Led C6 Mini 12v H3 | C20: 8000 | D20: =C20*1.4 -> 11200 | E20: =D20-C20 -> 3200 | F20: 4 | G20: =D20*0.95 -> 10640 | H20: =D20*1.21 -> 13552
A21: 661094215581 | B21: Kit Cree Led C6 Mini 12v 9004 | C21: 8000 | D21: =C21*1.4 -> 11200 | E21: =D21-C21 -> 3200 | F21: 3 | G21: =D21*0.95 -> 10640 | H21: =D21*1.21 -> 13552
A22: 661094215482 | B22: Kit Cree Led C6 Mini 12v H4 | C22: 8000 | D22: =C22*1.4 -> 11200 | E22: =D22-C22 -> 3200 | F22: 0 | G22: =D22*0.95 -> 10640 | H22: =D22*1.21 -> 13552
A23: 661094215567 | B23: Kit Cree Led C6 Mini 12v 9005 | C23: 8000 | D23: =C23*1.4 -> 11200 | E23: =D23-C23 -> 3200 | F23: 5 | G23: =D23*0.95 -> 10640 | H23: =D23*1.21 -> 13552
A24: 661094215529 | B24: Kit Cree Led C6 Mini 12v 9006 | C24: 8000 | D24: =C24*1.4 -> 11200 | E24: =D24-C24 -> 3200 | F24: 7 | G24: =D24*0.95 -> 10640 | H24: =D24*1.21 -> 13552
A25: 661094215550 | B25: Kit Cree Led C6 Mini 12v H27 | C25: 16000 | D25: =C25*1.4 -> 22400 | E25: =D25-C25 -> 6400 | F25: 3 | G25: =D25*0.95 -> 21280 | H25: =D25*1.21 -> 27104
A26: 661094215543 | B26: Kit Cree Led C6 Mini 12v H16-PSX | C26: 18000 | D26: =C26*1.4 -> 25200 | E26: =D26-C26 -> 7200 | F26: 1 | G26: =D26*0.95 -> 23940 | H26: =D26*1.21 -> 30492
A27: 661094215543 | B27: Kit Cree Led C6 Mini 12v PSX24W | C27: 18000 | D27: =C27*1.4 -> 25200 | E27: =D27-C27 -> 7200 | F27: 2 | G27: =D27*0.95 -> 23940 | H27: =D27*1.21 -> 30492
B28: Cable 2 hilos x 1,5 mm ( por metro) | C28: 2760 | D28: =C28*1.4 -> 3864 | E28: =D28-C28 -> 1104 | G28: =D28*0.95 -> 3670.8 | H28: =D28*1.21 -> 4675.44
D29: =C29*1.4 -> 0 | E29: =D29-C29 -> 0 | G29: =D29*0.95 -> 0 | H29: =D29*1.21 -> 0
D30: =C30*1.4 -> 0 | E30: =D30-C30 -> 0 | G30: =D30*0.95 -> 0 | H30: =D30*1.21 -> 0
D31: =C31*1.4 -> 0 | E31: =D31-C31 -> 0 | G31: =D31*0.95 -> 0 | H31: =D31*1.21 -> 0
D32: =C32*1.4 -> 0 | E32: =D32-C32 -> 0 | G32: =D32*0.95 -> 0 | H32: =D32*1.21 -> 0
D33: =C33*1.4 -> 0 | E33: =D33-C33 -> 0 | G33: =D33*0.95 -> 0 | H33: =D33*1.21 -> 0
D34: =C34*1.4 -> 0 | E34: =D34-C34 -> 0 | G34: =D34*0.95 -> 0 | H34: =D34*1.21 -> 0
D35: =C35*1.4 -> 0 | E35: =D35-C35 -> 0 | G35: =D35*0.95 -> 0 | H35: =D35*1.21 -> 0
D36: =C36*1.4 -> 0 | E36: =D36-C36 -> 0 | G36: =D36*0.95 -> 0 | H36: =D36*1.21 -> 0
D37: =C37*1.4 -> 0 | E37: =D37-C37 -> 0 | G37: =D37*0.95 -> 0 | H37: =D37*1.21 -> 0
D38: =C38*1.4 -> 0 | E38: =D38-C38 -> 0 | G38: =D38*0.95 -> 0 | H38: =D38*1.21 -> 0
D39: =C39*1.4 -> 0 | E39: =D39-C39 -> 0 | G39: =D39*0.95 -> 0 | H39: =D39*1.21 -> 0
D40: =C40*1.4 -> 0 | E40: =D40-C40 -> 0 | G40: =D40*0.95 -> 0 | H40: =D40*1.21 -> 0
... D496: =C496*1.4 -> 0 | E496: =D496-C496 -> 0 | G496: =D496*0.95 -> 0 | H496: =D496*1.21 -> 0
...

Sheet baterias
A1: {=_xlfn._xlws.FILTER(A5:H147,ISNUMBER(SEARCH(B2,A5:A147)))} -> #VALUE!
A2: BUSCAR =
B3: PRECIO CON LA ENTREGA DE LA USADA, SI NO SUMAR 5 %
A4: CODIGO | B4: PRODUCTO | C4: FABRICA | D4: PUBLICO | E4: GANANCIA | F4: STOCK | G4: DESC. 5 % | H4: IVA 21 %
A5: 02085MR200186 | B5: BATERIA GIAGNONI X 65 AMPER (AUTOS) | C5: 97 | D5: =C5*1.25 -> 121.25 | E5: =D5-C5 -> 24.25 | F5: 0 | G5: =D5*0.95 -> 115.1875 | H5: =D5*1.21 -> 146.7125
A6: 02022MR210278 | B6: BATERIA GIAGNONI X 65 AMPER REFORZADA (AUTOS) | C6: 112000 | D6: =C6*1.25 -> 140000 | E6: =D6-C6 -> 28000 | F6: 2 | G6: =D6*0.95 -> 133000 | H6: =D6*1.21 -> 169400
A7: 02068SE210166 | B7: BATERIA GIAGNONI 12 V X 110 AMPER "C" (PERKINS,CAMIONES) | C7: 200000 | D7: =C7*1.25 -> 250000 | E7: =D7-C7 -> 50000 | F7: 2 | G7: =D7*0.95 -> 237500 | H7: =D7*1.21 -> 302500
A8: 02035MR210150 | B8: BATERIA GIAGNONI 12 V X 110 AMPER "B" (AMAROK,S10,MERCEDEZ) | C8: 210000 | D8: =C8*1.25 -> 262500 | E8: =D8-C8 -> 52500 | F8: 2 | G8: =D8*0.95 -> 249375 | H8: =D8*1.21 -> 317625
A9: 01029MR341259 | B9: BATERIA GIAGNONI 12V X 90 AMPER "B" (RANGER,MASTER,F100) | C9: 170000 | D9: =C9*1.25 -> 212500 | E9: =D9-C9 -> 42500 | F9: 2 | G9: =D9*0.95 -> 201875 | H9: =D9*1.21 -> 257125
C10: 337684 | D10: =C10*1.25 -> 422105 | E10: =D10-C10 -> 84421 | G10: =D10*0.95 -> 400999.75 | H10: =D10*1.21 -> 510747.05
D11: =C11*1.25 -> 0 | E11: =D11-C11 -> 0 | G11: =D11*0.95 -> 0 | H11: =D11*1.21 -> 0
D12: =C12*1.25 -> 0 | E12: =D12-C12 -> 0 | G12: =D12*0.95 -> 0 | H12: =D12*1.21 -> 0
G13: =D13*0.95 -> 0 | H13: =D13*1.21 -> 0
D14: =C13*1.25 -> 0 | E14: =D14-C13 -> 0 | G14: =D14*0.95 -> 0 | H14: =D14*1.21 -> 0
D15: =C14*1.25 -> 0 | E15: =D15-C14 -> 0 | G15: =D15*0.95 -> 0 | H15: =D15*1.21 -> 0
D16: =C15*1.25 -> 0 | E16: =D16-C15 -> 0 | G16: =D16*0.95 -> 0 | H16: =D16*1.21 -> 0
D17: =C16*1.25 -> 0 | E17: =D17-C16 -> 0 | G17: =D17*0.95 -> 0 | H17: =D17*1.21 -> 0
D18: =C17*1.25 -> 0 | E18: =D18-C17 -> 0 | G18: =D18*0.95 -> 0 | H18: =D18*1.21 -> 0
D19: =C18*1.25 -> 0 | E19: =D19-C18 -> 0 | G19: =D19*0.95 -> 0 | H19: =D19*1.21 -> 0
D20: =C19*1.25 -> 0 | E20: =D20-C19 -> 0 | G20: =D20*0.95 -> 0 | H20: =D20*1.21 -> 0
D21: =C20*1.25 -> 0 | E21: =D21-C20 -> 0 | G21: =D21*0.95 -> 0 | H21: =D21*1.21 -> 0
D22: =C21*1.25 -> 0 | E22: =D22-C21 -> 0 | G22: =D22*0.95 -> 0 | H22: =D22*1.21 -> 0
D23: =C22*1.25 -> 0 | E23: =D23-C22 -> 0 | G23: =D23*0.95 -> 0 | H23: =D23*1.21 -> 0
D24: =C23*1.25 -> 0 | E24: =D24-C23 -> 0 | G24: =D24*0.95 -> 0 | H24: =D24*1.21 -> 0
D25: =C24*1.25 -> 0 | E25: =D25-C24 -> 0 | G25: =D25*0.95 -> 0 | H25: =D25*1.21 -> 0
D26: =C25*1.25 -> 0 | E26: =D26-C25 -> 0 | G26: =D26*0.95 -> 0 | H26: =D26*1.21 -> 0
E27: =D27-C26 -> 0 | G27: =D27*0.95 -> 0 | H27: =D27*1.21 -> 0
D28: =C28*1.25 -> 0 | E28: =D28-C28 -> 0 | G28: =D28*0.95 -> 0 | H28: =D28*1.21 -> 0
D29: =C29*1.4 -> 0 | E29: =D29-C29 -> 0 | G29: =D29*0.95 -> 0 | H29: =D29*1.21 -> 0
D30: =C30*1.4 -> 0 | E30: =D30-C30 -> 0 | G30: =D30*0.95 -> 0 | H30: =D30*1.21 -> 0
D31: =C31*1.4 -> 0 | E31: =D31-C31 -> 0 | G31: =D31*0.95 -> 0 | H31: =D31*1.21 -> 0
D32: =C32*1.4 -> 0 | E32: =D32-C32 -> 0 | G32: =D32*0.95 -> 0 | H32: =D32*1.21 -> 0
D33: =C33*1.4 -> 0 | E33: =D33-C33 -> 0 | G33: =D33*0.95 -> 0 | H33: =D33*1.21 -> 0
D34: =C34*1.4 -> 0 | E34: =D34-C34 -> 0 | G34: =D34*0.95 -> 0 | H34: =D34*1.21 -> 0
D35: =C35*1.4 -> 0 | E35: =D35-C35 -> 0 | G35: =D35*0.95 -> 0 | H35: =D35*1.21 -> 0
D36: =C36*1.4 -> 0 | E36: =D36-C36 -> 0 | G36: =D36*0.95 -> 0 | H36: =D36*1.21 -> 0
D37: =C37*1.4 -> 0 | E37: =D37-C37 -> 0 | G37: =D37*0.95 -> 0 | H37: =D37*1.21 -> 0
D38: =C38*1.4 -> 0 | E38: =D38-C38 -> 0 | G38: =D38*0.95 -> 0 | H38: =D38*1.21 -> 0
D39: =C39*1.4 -> 0 | E39: =D39-C39 -> 0 | G39: =D39*0.95 -> 0 | H39: =D39*1.21 -> 0
D40: =C40*1.4 -> 0 | E40: =D40-C40 -> 0 | G40: =D40*0.95 -> 0 | H40: =D40*1.21 -> 0
...

Sheet Electroventilador
A1: {=_xlfn._xlws.FILTER(A5:H147,ISNUMBER(SEARCH(B2,A5:A147)))} -> #VALUE!
A2: BUSCAR =
A4: CODIGO | B4: PRODUCTO | C4: FABRICA | D4: PUBLICO | E4: GANANCIA | F4: STOCK | G4: DESC. 5 % | H4: IVA 21 %
A5: OMER08EV'226 | B5: ELECTRO CHEVROLET CORSA 2 1.8 NAFTA 2-12 FIAT PALIO FIRE 1.3 | E5: =D5-C5 -> 0 | F5: 4 | G5: =D5*0.95 -> 0 | H5: =D5*1.21 -> 0
A6: OMER08EV'280 | B6: ELECTRO PEUGEOT PARTNER CITROEN BERLINGO 1.6 16V HDI 10-> | C6: 75508 | D6: =C6*1.4 -> 105711.2 | E6: =D6-C6 -> 30203.2 | F6: 4 | G6: =D6*0.95 -> 100425.64 | H6: =D6*1.21 -> 127910.55
A7: OMER08EV'275 | B7: ELECTRO VW FOX SURAN GOL TREND VOYAGE C/A.A | C7: 107949 | D7: =C7*1.4 -> 151128.6 | E7: =D7-C7 -> 43179.6 | F7: 1 | G7: =D7*0.95 -> 143572.17 | H7: =D7*1.21 -> 182865.61
A8: 13790334624 | B8: ELECTRO RENAULT MEGANE III CLIO II KANGOO LOGAN SANDERO | C8: 55932 | D8: =C8*1.4 -> 78304.8 | E8: =D8-C8 -> 22372.8 | F8: 8 | G8: =D8*0.95 -> 74389.56 | H8: =D8*1.21 -> 94748.808
A9: OMER08EV'212 | B9: ELECTROVENTILADOR PEUGEOT 206 1.6 C/A.A. 207 (FICHA NUEVA) | C9: 61525 | D9: =C9*1.4 -> 86135 | E9: =D9-C9 -> 24610 | F9: 8 | G9: =D9*0.95 -> 81828.25 | H9: =D9*1.21 -> 104223.35
A10: OMER08EV'275 | B10: ELECTROVENTILADOR VW FOX SURAN GOL TREND VOYAGE C/A.A. | C10: 107949 | D10: =C10*1.4 -> 151128.6 | E10: =D10-C10 -> 43179.6 | F10: 6 | G10: =D10*0.95 -> 143572.17 | H10: =D10*1.21 -> 182865.61
A11: OMER08EV-462 | B11: ELECTROVENTILADOR VW FOX SURAN GOL TREND VOYAGE C/A.A | C11: 53135 | D11: =C11*1.4 -> 74389 | E11: =D11-C11 -> 21254 | F11: 1 | G11: =D11*0.95 -> 70669.55 | H11: =D11*1.21 -> 90010.69
A12: OMER08EV'436 | B12: ELECTROVENTILADOR CHEVROLET OPEL ASTRA ZAFIRA VECTRA | C12: 60507 | D12: =C12*1.4 -> 84709.8 | E12: =D12-C12 -> 24202.8 | F12: 4 | G12: =D12*0.95 -> 80474.31 | H12: =D12*1.21 -> 102498.86
A13: OMER08EV'180 | B13: ELECTRO CHEVROLET ASTRA VW GOL SAVEIRO III IV POINTER C/A.A. | C13: 51457 | D13: =C13*1.4 -> 72039.8 | E13: =D13-C13 -> 20582.8 | F13: 4 | G13: =D13*0.95 -> 68437.81 | H13: =D13*1.21 -> 87168.158
A14: OMER08EV'434 | B14: ELECTRO CHEVROLET CORSA II 1.8 8V 04-> (FICHA C/RESISTENCIA) | C14: 51830 | D14: =C14*1.4 -> 72562 | E14: =D14-C14 -> 20732 | F14: 3 | G14: =D14*0.95 -> 68933.9 | H14: =D14*1.21 -> 87800.02
A15: WT'7331 | B15: CHEVROLET CORSA CLASSIC SPIRIT COMP. 1.4 2012+ WETZ | D15: =C15*1.4 -> 0 | E15: =D15-C15 -> 0 | F15: 1 | G15: =D15*0.95 -> 0 | H15: =D15*1.21 -> 0
A16: OMER08EV241 | B16: ELECTROVENTILADOR VW FOX SURAN MOTOR PRINCIPAL | C16: 93966 | D16: =C16*1.4 -> 131552.4 | E16: =D16-C16 -> 37586.4 | F16: 3 | G16: =D16*0.95 -> 124974.78 | H16: =D16*1.21 -> 159178.4
A17: OMER08EV'598 | B17: VOLSWAGEN POLO 1.6 15+ | D17: =C17*1.4 -> 0 | E17: =D17-C17 -> 0 | F17: 1 | G17: =D17*0.95 -> 0 | H17: =D17*1.21 -> 0
A18: 13790334637 | B18: ELECTROVENTILADOR VW GOL III SAVEIRO III IV POINTER S/A.A. | D18: =C18*1.4 -> 0 | E18: =D18-C18 -> 0 | F18: 1 | G18: =D18*0.95 -> 0 | H18: =D18*1.21 -> 0
A19: 1590344825 | B19: ELECTROVENTILADOR CHEVROLET ASTRA ZAFIRA | C19: 68436 | D19: =C19*1.4 -> 95810.4 | E19: =D19-C19 -> 27374.4 | F19: 1 | G19: =D19*0.95 -> 91019.88 | H19: =D19*1.21 -> 115930.58
A20: OMER08EV'316 | B20: ELECTROVENTILADOR CHEV. SONIC SPIN ONIX PRISMA COBALT | C20: 87254 | D20: =C20*1.4 -> 122155.6 | E20: =D20-C20 -> 34901.6 | F20: 2 | G20: =D20*0.95 -> 116047.82 | H20: =D20*1.21 -> 147808.28
A21: OMER08EV'459 | B21: ELECTRO CHEV ONIX PRISMA COBALT SONIC SPIN TRACKER | C21: 66447 | D21: =C21*1.4 -> 93025.8 | E21: =D21-C21 -> 26578.8 | F21: 2 | G21: =D21*0.95 -> 88374.51 | H21: =D21*1.21 -> 112561.22
A22: OMER08EV'582 | B22: ELECTROVENTILADOR FORD ECOSPORT KINETIC 2013 | C22: 53135 | D22: =C22*1.4 -> 74389 | E22: =D22-C22 -> 21254 | F22: 3 | G22: =D22*0.95 -> 70669.55 | H22: =D22*1.21 -> 90010.69
A23: OMER08EV'225 | B23: ELECTROVENTILADOR FORD ECOSPORT FIESTA MAX ONE | C23: 59864 | D23: =C23*1.4 -> 83809.6 | E23: =D23-C23 -> 23945.6 | F23: 5 | G23: =D23*0.95 -> 79619.12 | H23: =D23*1.21 -> 101409.62
A24: OMER08EV'583 | B24: ELECTROVENTILADOR FORD FIESTA KINETIC 1.6 10->13 | C24: 53695 | D24: =C24*1.4 -> 75173 | E24: =D24-C24 -> 21478 | F24: 4 | G24: =D24*0.95 -> 71414.35 | H24: =D24*1.21 -> 90959.33
B25: ELECTRO GATE CLIO II | D25: =C25*1.4 -> 0 | E25: =D25-C25 -> 0 | F25: 1 | G25: =D25*0.95 -> 0 | H25: =D25*1.21 -> 0
B26: ELECTRO DUSTER OROCH | D26: =C26*1.4 -> 0 | E26: =D26-C26 -> 0 | F26: 1 | G26: =D26*0.95 -> 0 | H26: =D26*1.21 -> 0
A27: 13790338825 | B27: ELECTROVENTILADOR VOLKSWAGEN BORA AUTOMATICO | C27: 84191 | D27: =C27*1.4 -> 117867.4 | E27: =D27-C27 -> 33676.4 | F27: 3 | G27: =D27*0.95 -> 111974.03 | H27: =D27*1.21 -> 142619.55
A28: 1590344821 | B28: ELECTROVENTILADOR VW BORA GOLF AUDI A3 MOTOR PRINCIPAL | C28: 96456 | D28: =C28*1.4 -> 135038.4 | E28: =D28-C28 -> 38582.4 | F28: 1 | G28: =D28*0.95 -> 128286.48 | H28: =D28*1.21 -> 163396.46
A29: OMER08EV'279 | B29: ELECTROVENTILADOR VW GOLF IV BORA C/A.A. ´AUXILIAR´ HELICE CHICA | C29: 83339 | D29: =C29*1.4 -> 116674.6 | E29: =D29-C29 -> 33335.6 | F29: 1 | G29: =D29*0.95 -> 110840.87 | H29: =D29*1.21 -> 141176.27
A30: OMER08EV'470 | B30: ELECTROVENTILADOR CHEV SONIC SPIN COBALT ONIX PRISMA C/ENCAUZADOR | C30: 86965 | D30: =C30*1.4 -> 121751 | E30: =D30-C30 -> 34786 | F30: 6 | G30: =D30*0.95 -> 115663.45 | H30: =D30*1.21 -> 147318.71
A31: 13790338810 | B31: ELECTROVENTILADOR FIAT PALIO SIENA C/ENCAUZADOR | C31: 93966 | D31: =C31*1.4 -> 131552.4 | E31: =D31-C31 -> 37586.4 | F31: 1 | G31: =D31*0.95 -> 124974.78 | H31: =D31*1.21 -> 159178.4
A32: OMER08EV'448 | B32: ELECTRO FIAT PALIO FIRE STRADA SIENA C/ENCAUZADOR | C32: 87503 | D32: =C32*1.4 -> 122504.2 | E32: =D32-C32 -> 35001.2 | F32: 2 | G32: =D32*0.95 -> 116378.99 | H32: =D32*1.21 -> 148230.08
A33: 1590371340 | B33: ELECTROVENTILADOR FIAT PALIO SIENA C/A.A TIPO GATE | C33: 84636 | D33: =C33*1.4 -> 118490.4 | E33: =D33-C33 -> 33854.4 | F33: 1 | G33: =D33*0.95 -> 112565.88 | H33: =D33*1.21 -> 143373.38
A34: OMER3115 | B34: ELECTRO FIAT PALIO 1.3 Y 1.0 S/AA | D34: =C34*1.4 -> 0 | E34: =D34-C34 -> 0 | F34: 1 | G34: =D34*0.95 -> 0 | H34: =D34*1.21 -> 0
A35: 1590371338 | B35: ELECTROVENTILADOR FIAT TORO 2.0 500X | C35: 72756 | D35: =C35*1.4 -> 101858.4 | E35: =D35-C35 -> 29102.4 | F35: 1 | G35: =D35*0.95 -> 96765.48 | H35: =D35*1.21 -> 123248.66
A36: 08EV-919 | B36: ELECTROVENTILADOR UNIVERSAL 24V 12" ASPAS RECTAS | C36: 94635 | D36: =C36*1.4 -> 132489 | E36: =D36-C36 -> 37854 | F36: 1 | G36: =D36*0.95 -> 125864.55 | H36: =D36*1.21 -> 160311.69
A37: 16790343892 | B37: ELECTROVENTILADOR 12V UNIVERSAL 10" EXTRACHATO | C37: 40292 | D37: =C37*1.4 -> 56408.8 | E37: =D37-C37 -> 16116.8 | F37: 3 | G37: =D37*0.95 -> 53588.36 | H37: =D37*1.21 -> 68254.648
A38: 10590337566 | B38: ELECTROVENTILADOR UNIVERSAL 12" 12V EXTRACHATO CURVO | C38: 45033 | D38: =C38*1.4 -> 63046.2 | E38: =D38-C38 -> 18013.2 | F38: 3 | G38: =D38*0.95 -> 59893.89 | H38: =D38*1.21 -> 76285.902
A39: OMER08EV'913 | B39: ELECTROVENTILADOR UNIVERSAL 24V 12" ASPAS RECTAS | C39: 37613 | D39: =C39*1.4 -> 52658.2 | E39: =D39-C39 -> 15045.2 | F39: 1 | G39: =D39*0.95 -> 50025.29 | H39: =D39*1.21 -> 63716.422
A40: OMER08EV910 | B40: ELECTROVENTILADOR UNIVERSAL 12V 10" ASPAS RECTAS | C40: 35823 | D40: =C40*1.4 -> 50152.2 | E40: =D40-C40 -> 14329.2 | F40: 1 | G40: =D40*0.95 -> 47644.59 | H40: =D40*1.21 -> 60684.162
A41: 1590344820 | B41: ELECTROVENTILADOR C/ENCAUZADOR REN LOGAN SANDERO DUSTER 1.4 1.6 14> | C41: 78429 | D41: =C41*1.4 -> 109800.6 | E41: =D41-C41 -> 31371.6 | F41: 1 | G41: =D41*0.95 -> 104310.57 | H41: =D41*1.21 -> 132858.73
...

Sheet OPTICAS
A1: {=_xlfn._xlws.FILTER(A5:H147,ISNUMBER(SEARCH(B2,A5:A147)))} -> #VALUE!
A2: BUSCAR =
A4: CODIGO | B4: PRODUCTO | C4: FABRICA | D4: PUBLICO | E4: GANANCIA | F4: STOCK | G4: DESC. 5 % | H4: IVA 21 %
A5: VIC'777I | B5: FARO IZQ. GOL / SENDA /SAVEIRO 91-95 | E5: =D5-C5 -> 0 | F5: 1 | G5: =D5*0.95 -> 0 | H5: =D5*1.21 -> 0
A6: 330128 | B6: FARO GOL 95-99 SAVEIRO 98-99 AMBAR | D6: =C6*1.4 -> 0 | E6: =D6-C6 -> 0 | F6: 1 | G6: =D6*0.95 -> 0 | H6: =D6*1.21 -> 0
A7: 31194 | B7: FARO FORD F100/150//250/350 DEL. AMBAR C/CHAPA SUJETADORA | D7: =C7*1.4 -> 0 | E7: =D7-C7 -> 0 | F7: 2 | G7: =D7*0.95 -> 0 | H7: =D7*1.21 -> 0
A8: VIC'723I | B8: FARO F-100 93-96 IZQUIERDO | D8: =C8*1.4 -> 0 | E8: =D8-C8 -> 0 | F8: 1 | G8: =D8*0.95 -> 0 | H8: =D8*1.21 -> 0
A9: 12355120D | B9: FARO TRASERO VW 2014+ DERECHO | D9: =C9*1.4 -> 0 | E9: =D9-C9 -> 0 | F9: 2 | G9: =D9*0.95 -> 0 | H9: =D9*1.21 -> 0
A10: 12355120I | B10: FARO TRASERO VW 2014+ IZQUIERDO | D10: =C10*1.4 -> 0 | E10: =D10-C10 -> 0 | F10: 1 | G10: =D10*0.95 -> 0 | H10: =D10*1.21 -> 0
A11: 7798035613335 | B11: FARO TOYOTA HILUX 2011-2015 BICOLOR DERECHO | D11: =C11*1.4 -> 0 | E11: =D11-C11 -> 0 | F11: 2 | G11: =D11*0.95 -> 0 | H11: =D11*1.21 -> 0
A12: 7798035613335 | B12: FARO TOYOTA HILUX 2011-2015 BICOLOR IZQUIERDO | D12: =C12*1.4 -> 0 | E12: =D12-C12 -> 0 | F12: 1 | G12: =D12*0.95 -> 0 | H12: =D12*1.21 -> 0
A13: 53230 | B13: FARO TRASERO TOYOTA HILUX 2001-2005 DERECHO | D13: =C13*1.4 -> 0 | E13: =D13-C13 -> 0 | F13: 2 | G13: =D13*0.95 -> 0 | H13: =D13*1.21 -> 0
A14: 53230 | B14: FARO TRASERO TOYOTA HILUX 2001-2005 IZQUIERDO | D14: =C14*1.4 -> 0 | E14: =D14-C14 -> 0 | F14: 3 | G14: =D14*0.95 -> 0 | H14: =D14*1.21 -> 0
A15: LA-OP021046 | B15: OPTICA FORD RANGER 04->09 | C15: 106365 | D15: =C15*1.4 -> 148911 | E15: =D15-C15 -> 42546 | F15: 1 | G15: =D15*0.95 -> 141465.45 | H15: =D15*1.21 -> 180182.31
A16: 36023 | B16: FARO TRASERO FORD RANGER 2004-2009 HUMO | D16: =C16*1.4 -> 0 | E16: =D16-C16 -> 0 | F16: 1 | G16: =D16*0.95 -> 0 | H16: =D16*1.21 -> 0
A17: 36023 | B17: FARO DELANTERO FORD RANGER 2004-2009 HUMO | D17: =C17*1.4 -> 0 | E17: =D17-C17 -> 0 | F17: 1 | G17: =D17*0.95 -> 0 | H17: =D17*1.21 -> 0
A18: 39013050D | B18: FARO TRASERO TOYOTA HILUX 16+ BI COLOR IZQUIERDO | D18: =C18*1.4 -> 0 | E18: =D18-C18 -> 0 | F18: 2 | G18: =D18*0.95 -> 0 | H18: =D18*1.21 -> 0
A19: 39013050I | B19: FARO TRASERO TOYOTA HILUX 16+ BI COLOR IZQUIERDO | D19: =C19*1.4 -> 0 | E19: =D19-C19 -> 0 | F19: 1 | G19: =D19*0.95 -> 0 | H19: =D19*1.21 -> 0
A20: 036111A | B20: FARO TRASERO FORD RANGER 2010-2012 ACRIL IZQ. | D20: =C20*1.4 -> 0 | E20: =D20-C20 -> 0 | F20: 2 | G20: =D20*0.95 -> 0 | H20: =D20*1.21 -> 0
A21: 036111A | B21: FARO TRASERO FORD RANGER 2010-2012 ACRIL IDERECHO | D21: =C21*1.4 -> 0 | E21: =D21-C21 -> 0 | F21: 2 | G21: =D21*0.95 -> 0 | H21: =D21*1.21 -> 0
A22: 7798035610464 | B22: FARO TRASERO FORD RANGER 2012+ 12-15 IZQ | D22: =C22*1.4 -> 0 | E22: =D22-C22 -> 0 | F22: 4 | G22: =D22*0.95 -> 0 | H22: =D22*1.21 -> 0
A23: 7798035610464 | B23: FARO TRASERO FORD RANGER 2012+ 12-15 DERECHO | D23: =C23*1.4 -> 0 | E23: =D23-C23 -> 0 | F23: 4 | G23: =D23*0.95 -> 0 | H23: =D23*1.21 -> 0
B24: FARO TRASERO FORD RANGER 2017-2023 P/ BULBO IZQ. | D24: =C24*1.4 -> 0 | E24: =D24-C24 -> 0 | F24: 1 | G24: =D24*0.95 -> 0 | H24: =D24*1.21 -> 0
B25: FARO TRASERO GOL POWER 2005-2013 | C25: 30000 | D25: =C25*1.4 -> 42000 | E25: =D25-C25 -> 12000 | F25: 2 | G25: =D25*0.95 -> 39900 | H25: =D25*1.21 -> 50820
D26: =C26*1.4 -> 0 | E26: =D26-C26 -> 0 | G26: =D26*0.95 -> 0 | H26: =D26*1.21 -> 0
D27: =C27*1.4 -> 0 | E27: =D27-C27 -> 0 | G27: =D27*0.95 -> 0 | H27: =D27*1.21 -> 0
D28: =C28*1.4 -> 0 | E28: =D28-C28 -> 0 | G28: =D28*0.95 -> 0 | H28: =D28*1.21 -> 0
D29: =C29*1.4 -> 0 | E29: =D29-C29 -> 0 | G29: =D29*0.95 -> 0 | H29: =D29*1.21 -> 0
D30: =C30*1.4 -> 0 | E30: =D30-C30 -> 0 | G30: =D30*0.95 -> 0 | H30: =D30*1.21 -> 0
D31: =C31*1.4 -> 0 | E31: =D31-C31 -> 0 | G31: =D31*0.95 -> 0 | H31: =D31*1.21 -> 0
D32: =C32*1.4 -> 0 | E32: =D32-C32 -> 0 | G32: =D32*0.95 -> 0 | H32: =D32*1.21 -> 0
D33: =C33*1.4 -> 0 | E33: =D33-C33 -> 0 | G33: =D33*0.95 -> 0 | H33: =D33*1.21 -> 0
D34: =C34*1.4 -> 0 | E34: =D34-C34 -> 0 | G34: =D34*0.95 -> 0 | H34: =D34*1.21 -> 0
D35: =C35*1.4 -> 0 | E35: =D35-C35 -> 0 | G35: =D35*0.95 -> 0 | H35: =D35*1.21 -> 0
D36: =C36*1.4 -> 0 | E36: =D36-C36 -> 0 | G36: =D36*0.95 -> 0 | H36: =D36*1.21 -> 0
D37: =C37*1.4 -> 0 | E37: =D37-C37 -> 0 | G37: =D37*0.95 -> 0 | H37: =D37*1.21 -> 0
... D496: =C496*1.4 -> 0 | E496: =D496-C496 -> 0 | G496: =D496*0.95 -> 0 | H496: =D496*1.21 -> 0
D497: =C497*1.4 -> 0 | E497: =D497-C497 -> 0 | G497: =D497*0.95 -> 0 | H497: =D497*1.21 -> 0 | I497: =D496*F496 -> 0
D498: =C498*1.4 -> 0 | E498: =D498-C498 -> 0 | G498: =D498*0.95 -> 0 | H498: =D498*1.21 -> 0 | I498: =D497*F497 -> 0
D499: =C499*1.4 -> 0 | E499: =D499-C499 -> 0 | G499: =D499*0.95 -> 0 | H499: =D499*1.21 -> 0 | I499: =D498*F498 -> 0
...

Sheet copiar
A1: {=_xlfn._xlws.FILTER(A5:H147,ISNUMBER(SEARCH(B2,A5:A147)))} -> #VALUE!
A2: BUSCAR =
A4: CODIGO | B4: PRODUCTO | C4: FABRICA | D4: PUBLICO | E4: GANANCIA | F4: STOCK | G4: DESC. 5 % | H4: IVA 21 %
E5: =D5-C5 -> 0 | G5: =D5*0.95 -> 0 | H5: =D5*1.21 -> 0
D6: =C6*1.4 -> 0 | E6: =D6-C6 -> 0 | G6: =D6*0.95 -> 0 | H6: =D6*1.21 -> 0
D7: =C7*1.4 -> 0 | E7: =D7-C7 -> 0 | G7: =D7*0.95 -> 0 | H7: =D7*1.21 -> 0
D8: =C8*1.4 -> 0 | E8: =D8-C8 -> 0 | G8: =D8*0.95 -> 0 | H8: =D8*1.21 -> 0
D9: =C9*1.4 -> 0 | E9: =D9-C9 -> 0 | G9: =D9*0.95 -> 0 | H9: =D9*1.21 -> 0
D10: =C10*1.4 -> 0 | E10: =D10-C10 -> 0 | G10: =D10*0.95 -> 0 | H10: =D10*1.21 -> 0
D11: =C11*1.4 -> 0 | E11: =D11-C11 -> 0 | G11: =D11*0.95 -> 0 | H11: =D11*1.21 -> 0
D12: =C12*1.4 -> 0 | E12: =D12-C12 -> 0 | G12: =D12*0.95 -> 0 | H12: =D12*1.21 -> 0
D13: =C13*1.4 -> 0 | E13: =D13-C13 -> 0 | G13: =D13*0.95 -> 0 | H13: =D13*1.21 -> 0
D14: =C14*1.4 -> 0 | E14: =D14-C14 -> 0 | G14: =D14*0.95 -> 0 | H14: =D14*1.21 -> 0
D15: =C15*1.4 -> 0 | E15: =D15-C15 -> 0 | G15: =D15*0.95 -> 0 | H15: =D15*1.21 -> 0
D16: =C16*1.4 -> 0 | E16: =D16-C16 -> 0 | G16: =D16*0.95 -> 0 | H16: =D16*1.21 -> 0
D17: =C17*1.4 -> 0 | E17: =D17-C17 -> 0 | G17: =D17*0.95 -> 0 | H17: =D17*1.21 -> 0
... D496: =C496*1.4 -> 0 | E496: =D496-C496 -> 0 | G496: =D496*0.95 -> 0 | H496: =D496*1.21 -> 0
D497: =C497*1.4 -> 0 | E497: =D497-C497 -> 0 | G497: =D497*0.95 -> 0 | H497: =D497*1.21 -> 0 | I497: =D496*F496 -> 0
D498: =C498*1.4 -> 0 | E498: =D498-C498 -> 0 | G498: =D498*0.95 -> 0 | H498: =D498*1.21 -> 0 | I498: =D497*F497 -> 0
D499: =C499*1.4 -> 0 | E499: =D499-C499 -> 0 | G499: =D499*0.95 -> 0 | H499: =D499*1.21 -> 0 | I499: =D498*F498 -> 0
D500: =C500*1.4 -> 0 | E500: =D500-C500 -> 0 | G500: =D500*0.95 -> 0 | H500: =D500*1.21 -> 0 | I500: =D499*F499 -> 0
D501: =C501*1.4 -> 0 | E501: =D501-C501 -> 0 | G501: =D501*0.95 -> 0 | H501: =D501*1.21 -> 0 | I501: =D500*F500 -> 0
D502: =C502*1.4 -> 0 | E502: =D502-C502 -> 0 | G502: =D502*0.95 -> 0 | H502: =D502*1.21 -> 0 | I502: =D501*F501 -> 0
D503: =C503*1.4 -> 0 | E503: =D503-C503 -> 0 | G503: =D503*0.95 -> 0 | H503: =D503*1.21 -> 0 | I503: =D502*F502 -> 0
D504: =C504*1.4 -> 0 | E504: =D504-C504 -> 0 | G504: =D504*0.95 -> 0 | H504: =D504*1.21 -> 0 | I504: =D503*F503 -> 0
D505: =C505*1.4 -> 0 | E505: =D505-C505 -> 0 | G505: =D505*0.95 -> 0 | H505: =D505*1.21 -> 0 | I505: =D504*F504 -> 0
D506: =C506*1.4 -> 0 | E506: =D506-C506 -> 0 | G506: =D506*0.95 -> 0 | H506: =D506*1.21 -> 0 | I506: =D505*F505 -> 0
D507: =C507*1.4 -> 0 | E507: =D507-C507 -> 0 | G507: =D507*0.95 -> 0 | H507: =D507*1.21 -> 0 | I507: =D506*F506 -> 0
D508: =C508*1.4 -> 0 | E508: =D508-C508 -> 0 | G508: =D508*0.95 -> 0 | H508: =D508*1.21 -> 0 | I508: =D507*F507 -> 0
... D859: =C859*1.4 -> 0 | E859: =D859-C859 -> 0 | G859: =D859*0.95 -> 0 | H859: =D859*1.21 -> 0 | I859: =D858*F858 -> 0
I860: =D859*F859 -> 0
I861: =D860*F860 -> 0

Sheet Ajustes
A1: AJUSTES PERMANENTES DE PRODUCTOS
A2: Copiá “FILA ORIGINAL” desde el buscador. Ingresá una sola vez cada fila y completá NUEVO FABRICA y/o NUEVO STOCK.
A4: FILA ORIGINAL | B4: CODIGO | C4: PRODUCTO | D4: NUEVO FABRICA | E4: NUEVO STOCK
B5: {=IF(A5="","",IFERROR(INDEX(EQUIPAMIENTO!$A:$A,A5),"FILA INVÁLIDA"))} | C5: {=IF(A5="","",IFERROR(INDEX(EQUIPAMIENTO!$B:$B,A5),""))}
B6: {=IF(A6="","",IFERROR(INDEX(EQUIPAMIENTO!$A:$A,A6),"FILA INVÁLIDA"))} | C6: {=IF(A6="","",IFERROR(INDEX(EQUIPAMIENTO!$B:$B,A6),""))}
B7: {=IF(A7="","",IFERROR(INDEX(EQUIPAMIENTO!$A:$A,A7),"FILA INVÁLIDA"))} | C7: {=IF(A7="","",IFERROR(INDEX(EQUIPAMIENTO!$B:$B,A7),""))}
B8: {=IF(A8="","",IFERROR(INDEX(EQUIPAMIENTO!$A:$A,A8),"FILA INVÁLIDA"))} | C8: {=IF(A8="","",IFERROR(INDEX(EQUIPAMIENTO!$B:$B,A8),""))}
B9: {=IF(A9="","",IFERROR(INDEX(EQUIPAMIENTO!$A:$A,A9),"FILA INVÁLIDA"))} | C9: {=IF(A9="","",IFERROR(INDEX(EQUIPAMIENTO!$B:$B,A9),""))}
B10: {=IF(A10="","",IFERROR(INDEX(EQUIPAMIENTO!$A:$A,A10),"FILA INVÁLIDA"))} | C10: {=IF(A10="","",IFERROR(INDEX(EQUIPAMIENTO!$B:$B,A10),""))}
B11: {=IF(A11="","",IFERROR(INDEX(EQUIPAMIENTO!$A:$A,A11),"FILA INVÁLIDA"))} | C11: {=IF(A11="","",IFERROR(INDEX(EQUIPAMIENTO!$B:$B,A11),""))}
B12: {=IF(A12="","",IFERROR(INDEX(EQUIPAMIENTO!$A:$A,A12),"FILA INVÁLIDA"))} | C12: {=IF(A12="","",IFERROR(INDEX(EQUIPAMIENTO!$B:$B,A12),""))}
B13: {=IF(A13="","",IFERROR(INDEX(EQUIPAMIENTO!$A:$A,A13),"FILA INVÁLIDA"))} | C13: {=IF(A13="","",IFERROR(INDEX(EQUIPAMIENTO!$B:$B,A13),""))}
B14: {=IF(A14="","",IFERROR(INDEX(EQUIPAMIENTO!$A:$A,A14),"FILA INVÁLIDA"))} | C14: {=IF(A14="","",IFERROR(INDEX(EQUIPAMIENTO!$B:$B,A14),""))}
B15: {=IF(A15="","",IFERROR(INDEX(EQUIPAMIENTO!$A:$A,A15),"FILA INVÁLIDA"))} | C15: {=IF(A15="","",IFERROR(INDEX(EQUIPAMIENTO!$B:$B,A15),""))}
B16: {=IF(A16="","",IFERROR(INDEX(EQUIPAMIENTO!$A:$A,A16),"FILA INVÁLIDA"))} | C16: {=IF(A16="","",IFERROR(INDEX(EQUIPAMIENTO!$B:$B,A16),""))}
... B104: {=IF(A104="","",IFERROR(INDEX(EQUIPAMIENTO!$A:$A,A104),"FILA INVÁLIDA"))} | C104: {=IF(A104="","",IFERROR(INDEX(EQUIPAMIENTO!$B:$B,A104),""))}
